Workbook

Sheet Index
B2: # | C2: Steps | D2: POC | E2: Links | F2: Day (t)
B3: 1 | C3: Input Stress levels and respective time horizons | D3: All | E3: Link | F3: 0
B4: =B3+1 -> 2 | C4: Input Disbursals (Stressed) | D4: Business | E4: Link | F4: 2
B5: =B4+1 -> 3 | C5: Input ENR (Stressed - pre writeoff) | D5: Finance | E5: Link | F5: 4 | G5: CoF assumption - Treasury
B6: =B5+1 -> 4 | C6: Input ANR (Stressed - pre writeoff) | D6: Finance | E6: Link | F6: 4
B7: =B6+1 -> 5 | C7: Input CoC (Plan) | D7: AIM | E7: Link | F7: 6 | G7: Credit Stress
B8: =B7+1 -> 6 | C8: Update NCL (Stressed Disbursal impact) | D8: AIM | E8: Link | F8: 6
B9: =B8+1 -> 7 | C9: Input PDLGD (Plan) | D9: AIM | E9: Link | F9: 6
B10: =B9+1 -> 8 | C10: Update Stress Parameters | D10: AIM | E10: Link | F10: 6
B11: =B10+1 -> 9 | C11: Update NCL and ECL | D11: AIM | E11: Link | F11: 6
B12: =B11+1 -> 10 | C12: Update Stage Distribution | D12: AIM | E12: Link | F12: 6
B13: =B12+1 -> 11 | C13: Update ENR (Stressed - post writeoff) | D13: Finance | E13: Link | F13: 8
B14: =B13+1 -> 12 | C14: Update ANR (Stressed - post writeoff) | D14: Finance | E14: Link | F14: 8
B15: =B14+1 -> 13 | C15: Input Financials for Stressed scenario (with Stress inputs on margin, expense, CoF) | D15: Finance/Treasury | E15: Link | F15: 10
B16: =B15+1 -> 14 | C16: Output Summary | D16: Finance | E16: Link | F16: 11
B17: =B16+1 -> 15 | C17: Stress test deck | D17: AIM | F17: 12

Sheet Assumptions
C3: Assumptions
C5: Base Scenario | D5: The base scenario is considered as revised ABP plan for FY25-FY27
C7: Stress Scenario | D7: The stress scenario is considered for the period of 30 months with split in 3 levels.
D9: Stress Level | E9: Definition | F9: Stress Period | G9: Disbursal
G10: HL + LAP | H10: DF
D11: SL1: Slowdown | E11: 1 in 7 years | F11: 6 months (Apr’24 to Sep’24) | G11: @60% of Base scenario | H11: @40% of Base scenario
D12: SL2: Recession | E12: 1 in 25 years | F12: 12 months (Oct’24 to Sep'25) | G12: @40% of Base scenario | H12: @20% of Base scenario
D13: SL3: Recovery | E13: 1 in 10 years | F13: 12 months (Oct’25 to Sep’26) | G13: @60% of Base scenario | H13: @40% of Base scenario
D14: BAU | F14: 6 months (Oct’26 to Mar’27) | G14: @100% of Base scenario | H14: @100% of Base scenario
C17: Stress Methodology | D17: Parameter | E17: Stress Methodology
D18: PD | E18: Base-line PD is stressed through Vasicek equation to get stressed PD across stress levels
D19: LGD | E19: Compute the downturn LGD as against Base-line LGD basis till inception trend
D20: NCL | E20: Compute stressed NCL by using Vasicek formula across 3 levels of stress
D21: ECL (PnL) | E21: 1- Stage distribution is worsened basis the historical stage distribution observed after covid wave 1 , some improvement is considered factoring better sourcing quality post covid
E22: 2- ECL rate for Stage-1 is worsened by extent of worsening of stage 2
E23: 3- Plan overlay is kept same as base period
E24: 4- Additional overlay has been built on ONAN pool to get the PCR of ONAN pool equal to stage 3 ECL rates
E25: 5- Actual ECL BS is computed on stressed ENR
D26: NPA | E26: 1 - 90 + GNPA is computed using worsened stage distribution
E27: 2- ONAN GNPA is computed using Non ONAN to ONAN pool ratio in stage2 of base scenario
E28: 3- Model PCR for 90+ GNPA and ONAN GNPA is same as base scenario
E29: 4- Additional overlay has been built on ONAN pool maintain stage 3 model PCR

Sheet Summary-S
E2: ABP | I2: Stress Scenario | M2: FY19-FY23 | Z2: ABP (revised) plan | AD2: Stress Scenario (Revised)
E3: FY25 | F3: FY26 | G3: FY27 | I3: FY25 | J3: FY26 | K3: FY27 | M3: FY19 | N3: FY20 | O3: FY21 | P3: FY22 | Q3: FY23 | Z3: FY24 | AA3: FY25 | AB3: FY26 | AD3: FY24 | AE3: FY25 | AF3: FY26
D4: GWO | E4: =Summary!E4 -> 548.34973 | F4: =Summary!F4 -> 645.75647 | G4: =Summary!G4 -> 790.29476 | I4: =Summary!I4 -> 548.34973 | J4: =Summary!J4 -> 764.78404 | K4: =Summary!K4 -> 929.38938 | M4: 393.85129 | N4: 442.05321 | O4: 904.60849 | P4: 457.59212 | Q4: 1797.0578 | Z4: 531.41761 | AA4: 1005.6938 | AB4: 776.19789 | AD4: 531.41761 | AE4: 1165.4088 | AF4: 894.97604
D5: Recovery | E5: =Summary!E5 -> 94.402361 | F5: =Summary!F5 -> 121.03769 | G5: =Summary!G5 -> 138.43137 | I5: =Summary!I5 -> 90.907807 | J5: =Summary!J5 -> 115.33068 | K5: =Summary!K5 -> 135.62991 | M5: 237.7953 | N5: 158.96618 | O5: 160.16087 | P5: 121.69172 | Q5: 667.84907 | Z5: 97.440846 | AA5: 169.04768 | AB5: 166.23342 | AD5: 91.496518 | AE5: 155.32698 | AF5: 159.39922
D6: NCL | E6: =Summary!E6 -> 453.94737 | F6: =Summary!F6 -> 524.71878 | G6: =Summary!G6 -> 651.8634 | I6: =Summary!I6 -> 457.44192 | J6: =Summary!J6 -> 649.45336 | K6: =Summary!K6 -> 793.75947 | M6: =M4-M5 -> 156.05599 | N6: =N4-N5 -> 283.08703 | O6: =O4-O5 -> 744.44762 | P6: =P4-P5 -> 335.9004 | Q6: =Q4-Q5 -> 1129.2087 | Z6: 433.97676 | AA6: 836.64616 | AB6: 609.96447 | AD6: 439.92109 | AE6: 1010.0819 | AF6: 735.57682
D7: ECL Pnl | E7: =Summary!E9 -> 170.67294 | F7: =Summary!F9 -> 279.45746 | G7: =Summary!G9 -> 344.84454 | I7: =Summary!I9 -> 596.03728 | J7: =Summary!J9 -> 125.20797 | K7: =Summary!K9 -> 121.59493 | M7: =SUM(#REF!) -> #REF! | N7: =SUM(#REF!) -> #REF! | O7: =SUM(#REF!) -> #REF! | P7: =SUM(#REF!) -> #REF! | Q7: =SUM(#REF!) -> #REF! | Z7: 192.31741 | AA7: 74.168555 | AB7: 431.20279 | AD7: 568.2236 | AE7: 105.61727 | AF7: 136.05036
D8: COC | E8: =Summary!E10 -> 624.6203 | F8: =Summary!F10 -> 804.17624 | G8: =Summary!G10 -> 996.70794 | I8: =Summary!I10 -> 1053.4792 | J8: =Summary!J10 -> 774.66133 | K8: =Summary!K10 -> 915.35441 | M8: =M4-M5+#REF!+#REF! -> #REF! | N8: =N4-N5+#REF!+#REF! -> #REF! | O8: =O4-O5+#REF!+#REF! -> #REF! | P8: =P4-P5+#REF!+#REF! -> #REF! | Q8: =Q4-Q5+#REF!+#REF! -> #REF! | R8: 1280.2768 | S8: 1575.0411 | T8: 781.41958 | X8: =SUM(I8:K8)/SUM(E8:G8) -> 1.1311028 | Z8: 626.29417 | AA8: 910.81471 | AB8: 1041.1673 | AD8: 1008.1447 | AE8: 1115.6991 | AF8: 871.62718 | AH8: =SUM(AD8:AF8)/SUM(Z8:AB8) -> 1.1618116
D9: CoC % | E9: =Summary!E11 -> 0.0060022903 | F9: =Summary!F11 -> 0.005594111 | G9: =Summary!G11 -> 0.0053038379 | I9: =Summary!I11 -> 0.011197131 | J9: =Summary!J11 -> 0.0077192859 | K9: =Summary!K11 -> 0.0072623405 | M9: =M8/M10 -> #REF! | N9: =N8/N10 -> #REF! | O9: =O8/O10 -> #REF! | P9: =P8/P10 -> #REF! | Q9: =Q8/Q10 -> #REF! | R9: 0.018933056 | S9: 0.021166365 | T9: 0.0077730378 | Z9: 0.0082141274 | AA9: 0.0082016771 | AB9: 0.0068720397 | AD9: 0.014751193 | AE9: 0.014210265 | AF9: 0.0083728501
D10: ANR | E10: =Summary!E13 -> 104063.66 | F10: =Summary!F13 -> 143754.07 | G10: =Summary!G13 -> 187922.02 | I10: =Summary!I13 -> 94084.743 | J10: =Summary!J13 -> 100354.01 | K10: =Summary!K13 -> 126041.24 | M10: 30191.291 | N10: 39210.151 | O10: 42720.108 | P10: 42630.648 | Q10: 54946.128 | Z10: 76245.978 | AA10: 111052.25 | AB10: 151507.75 | AD10: 68343.266 | AE10: 78513.605 | AF10: 104101.61
D11: ENR | E11: =Summary!E14 -> 112136.8 | F11: =Summary!F14 -> 150480.17 | G11: =Summary!G14 -> 193146.81 | I11: =Summary!I14 -> 86930.596 | J11: =Summary!J14 -> 92702.224 | K11: =Summary!K14 -> 143181.26 | M11: 30645.169 | N11: 39398.285 | O11: 38275.721 | P11: 41260.274 | Q11: 59276.646 | Z11: 89826.036 | AA11: 125498.39 | AB11: 162285.83 | AD11: 65255.747 | AE11: 77975.775 | AF11: 121832.96
D12: ECL BS | E12: =Summary!E15 -> 1839.2751 | F12: =Summary!F15 -> 2118.7326 | G12: =Summary!G15 -> 2463.5771 | I12: =Summary!I15 -> 2264.6395 | J12: =Summary!J15 -> 2389.8474 | K12: =Summary!K15 -> 2511.4424 | M12: 468.565 | N12: =M12+#REF! -> #REF! | O12: =N12+#REF! -> #REF! | P12: =O12+#REF! -> #REF! | Q12: =P12+#REF! -> #REF! | Z12: 1801.2291 | AA12: 1875.3977 | AB12: 2306.6005 | AD12: 2177.1358 | AE12: 2282.7531 | AF12: 2418.8035
D13: ECL BS/ENR | E13: =Summary!E16 -> 0.016402065 | F13: =Summary!F16 -> 0.014079812 | G13: =Summary!G16 -> 0.012754946 | I13: =Summary!I16 -> 0.026051121 | J13: =Summary!J16 -> 0.025779828 | K13: =Summary!K16 -> 0.017540301 | M13: =M12/M11 -> 0.015290012 | N13: =N12/N11 -> #REF! | O13: =O12/O11 -> #REF! | P13: =P12/P11 -> #REF! | Q13: =Q12/Q11 -> #REF! | Z13: 0.020052417 | AA13: 0.014943599 | AB13: 0.014213197 | AD13: 0.033363128 | AE13: 0.029275158 | AF13: 0.019853442
D14: GNPA% | E14: =Summary!E20 -> 0.020403727 | F14: =Summary!F20 -> 0.01714911 | G14: =Summary!G20 -> 0.015114985 | I14: =Summary!I20 -> 0.035715322 | J14: =Summary!J20 -> 0.037408138 | K14: =Summary!K20 -> 0.023801644 | M14: 0.020678312 | N14: 0.036817477 | O14: 0.056028682 | P14: 0.062302654 | Q14: 0.037431908 | R14: 0.069741801 | S14: 0.092798823 | T14: 0.051739469 | U14: =I14/E14 -> 1.7504313 | V14: =J14/F14 -> 2.1813457 | W14: =K14/G14 -> 1.5747051 | Z14: 0.027027797 | AA14: 0.018645964 | AB14: 0.015389441 | AD14: 0.04668013 | AE14: 0.045474874 | AF14: 0.024471418
D15: NNPA% | E15: =Summary!E21 -> 0.01335173 | F15: =Summary!F21 -> 0.011471243 | G15: =Summary!G21 -> 0.010290472 | I15: =Summary!I21 -> 0.021573257 | J15: =Summary!J21 -> 0.02313496 | K15: =Summary!K21 -> 0.01487465 | M15: 0.012300268 | N15: 0.019536555 | O15: 0.028748404 | P15: 0.030408628 | Q15: 0.023407939 | R15: 0.046627375 | S15: 0.066861049 | T15: 0.037048977 | U15: =(#REF!-#REF!)+(#REF!*5%) -> #REF! | Z15: 0.017790838 | AA15: 0.013233197 | AB15: 0.010967345 | AD15: 0.02641212 | AE15: 0.028454543 | AF15: 0.015351205

Sheet Summary
E2: ABP | I2: Stress Scenario | M2: FY19-FY23 | Z2: ABP (revised) plan | AD2: Stress Scenario (Revised)
E3: FY25 | F3: FY26 | G3: FY27 | I3: FY25 | J3: FY26 | K3: FY27 | M3: FY19 | N3: FY20 | O3: FY21 | P3: FY22 | Q3: FY23 | Z3: FY24 | AA3: FY25 | AB3: FY26 | AD3: FY24 | AE3: FY25 | AF3: FY26
D4: GWO | E4: =SUM('Plan - CoC'!D4:O6) -> 548.34973 | F4: =SUM('Plan - CoC'!P4:AA6) -> 645.75647 | G4: =SUM('Plan - CoC'!AB4:AM6) -> 790.29476 | I4: ='MOM Summary'!BM3 -> 548.34973 | J4: ='MOM Summary'!BN3 -> 764.78404 | K4: ='MOM Summary'!BO3 -> 929.38938 | M4: 393.85129 | N4: 442.05321 | O4: 904.60849 | P4: 457.59212 | Q4: 1797.0578 | Z4: 531.41761 | AA4: 1005.6938 | AB4: 776.19789 | AD4: 531.41761 | AE4: 1165.4088 | AF4: 894.97604
D5: Recovery | E5: =SUM('Plan - CoC'!D10:O12) -> 94.402361 | F5: =SUM('Plan - CoC'!P10:AA12) -> 121.03769 | G5: =SUM('Plan - CoC'!AB10:AM12) -> 138.43137 | I5: ='MOM Summary'!BM9 -> 90.907807 | J5: ='MOM Summary'!BN9 -> 115.33068 | K5: ='MOM Summary'!BO9 -> 135.62991 | M5: 237.7953 | N5: 158.96618 | O5: 160.16087 | P5: 121.69172 | Q5: 667.84907 | Z5: 97.440846 | AA5: 169.04768 | AB5: 166.23342 | AD5: 91.496518 | AE5: 155.32698 | AF5: 159.39922
D6: NCL | E6: =SUM('Input - NCL'!D10:O10) -> 453.94737 | F6: =SUM('Input - NCL'!P10:AA10) -> 524.71878 | G6: =SUM('Input - NCL'!AB10:AM10) -> 651.8634 | I6: =I4-I5 -> 457.44192 | J6: =J4-J5 -> 649.45336 | K6: =K4-K5 -> 793.75947 | M6: =M4-M5 -> 156.05599 | N6: =N4-N5 -> 283.08703 | O6: =O4-O5 -> 744.44762 | P6: =P4-P5 -> 335.9004 | Q6: =Q4-Q5 -> 1129.2087 | Z6: 433.97676 | AA6: 836.64616 | AB6: 609.96447 | AD6: 439.92109 | AE6: 1010.0819 | AF6: 735.57682
D7: ECL Model | E7: =SUM('Calculation - NCL and ECL'!F19:Q21) -> 212.49193 | F7: =SUM('Calculation - NCL and ECL'!R19:AC21) -> 317.72917 | G7: =SUM('Calculation - NCL and ECL'!AD19:AO21) -> 393.58197 | I7: ='MOM Summary'!BM15 -> 468.63553 | J7: ='MOM Summary'!BN15 -> 153.07826 | K7: ='MOM Summary'!BO15 -> 150.69271 | M7: -253.35745 | N7: 567.72418 | O7: 1060.3683 | P7: 335.76411 | Q7: -812.78953 | Z7: 349.21297 | AA7: 180.89224 | AB7: 445.01657 | AD7: 519.27564 | AE7: 188.4991 | AF7: 177.0906
D8: Overlay | E8: =SUM('Calculation - NCL and ECL'!F37:Q39) -> -41.818993 | F8: =SUM('Calculation - NCL and ECL'!R37:AC39) -> -38.27171 | G8: =+SUM('Calculation - NCL and ECL'!AD37:AO39) -> -48.73743 | I8: ='MOM Summary'!BM21 -> 127.40175 | J8: ='MOM Summary'!BN21 -> -27.870289 | K8: ='MOM Summary'!BO21 -> -29.097773 | M8: 0 | N8: 0 | Z8: -156.89556 | AA8: -106.72369 | AB8: -13.813785 | AD8: 48.947962 | AE8: -82.881832 | AF8: -41.040235
D9: ECL Pnl | E9: =SUM(E7:E8) -> 170.67294 | F9: =SUM(F7:F8) -> 279.45746 | G9: =SUM(G7:G8) -> 344.84454 | I9: =SUM(I7:I8) -> 596.03728 | J9: =SUM(J7:J8) -> 125.20797 | K9: =SUM(K7:K8) -> 121.59493 | M9: =SUM(M7:M8) -> -253.35745 | N9: =SUM(N7:N8) -> 567.72418 | O9: =SUM(O7:O8) -> 1060.3683 | P9: =SUM(P7:P8) -> 335.76411 | Q9: =SUM(Q7:Q8) -> -812.78953 | Z9: 192.31741 | AA9: 74.168555 | AB9: 431.20279 | AD9: 568.2236 | AE9: 105.61727 | AF9: 136.05036
D10: COC (with overlay) | E10: =E4-E5+E7+E8 -> 624.6203 | F10: =F4-F5+F7+F8 -> 804.17624 | G10: =G4-G5+G7+G8 -> 996.70794 | H10: =I10/E10 -> 1.6865913 | I10: =I4-I5+I7+I8 -> 1053.4792 | J10: =J4-J5+J7+J8 -> 774.66133 | K10: =K4-K5+K7+K8 -> 915.35441 | L10: =SUM(I10:K10)/SUM(E10:G10) -> 1.1311028 | M10: =M4-M5+M7+M8 -> -97.301456 | N10: =N4-N5+N7+N8 -> 850.81121 | O10: =O4-O5+O7+O8 -> 1804.8159 | P10: =P4-P5+P7+P8 -> 671.66451 | Q10: =Q4-Q5+Q7+Q8 -> 316.41915 | R10: 1280.2768 | S10: 1575.0411 | T10: 781.41958 | X10: =SUM(I10:K10)/SUM(E10:G10) -> 1.1311028 | Z10: 626.29417 | AA10: 910.81471 | AB10: 1041.1673 | AC10: =AD10/Z10 -> 1.6096983 | AD10: 1008.1447 | AE10: 1115.6991 | AF10: 871.62718 | AH10: =SUM(AD10:AF10)/SUM(Z10:AB10) -> 1.1618116
D11: CoC % | E11: =E10/E13 -> 0.0060022903 | F11: =F10/F13 -> 0.005594111 | G11: =G10/G13 -> 0.0053038379 | I11: =I10/I13 -> 0.011197131 | J11: =J10/J13 -> 0.0077192859 | K11: =K10/K13 -> 0.0072623405 | M11: =M10/M13 -> -0.0032228319 | N11: =N10/N13 -> 0.021698749 | O11: =O10/O13 -> 0.042247457 | P11: =P10/P13 -> 0.015755437 | Q11: =Q10/Q13 -> 0.0057587162 | R11: 0.018933056 | S11: 0.021166365 | T11: 0.0077730378 | Z11: 0.0082141274 | AA11: 0.0082016771 | AB11: 0.0068720397 | AD11: 0.014751193 | AE11: 0.014210265 | AF11: 0.0083728501
D12: Disbursals | E12: =SUM('Input - Disbursals'!D9:O9) -> 65610 | F12: =SUM('Input - Disbursals'!P9:AA9) -> 79000 | G12: =SUM('Input - Disbursals'!AB9:AM9) -> 91000 | I12: =SUM('Input - Disbursals'!D3:O3) -> 31451.25 | J12: =SUM('Input - Disbursals'!P3:AA3) -> 30923.414 | K12: =SUM('Input - Disbursals'!AB3:AM3) -> 81642.115 | Z12: 48926.841 | AA12: 65608.78 | AB12: 76267.656 | AD12: 21651.841 | AE12: 31322.075 | AF12: 68718.496
D13: ANR | E13: =AVERAGE('Input - ANR'!D15:O15) -> 104063.66 | F13: =AVERAGE('Input - ANR'!P15:AA15) -> 143754.07 | G13: =AVERAGE('Input - ANR'!AB15:AM15) -> 187922.02 | I13: ='MOM Summary'!BM45 -> 94084.743 | J13: ='MOM Summary'!BN45 -> 100354.01 | K13: ='MOM Summary'!BO45 -> 126041.24 | M13: 30191.291 | N13: 39210.151 | O13: 42720.108 | P13: 42630.648 | Q13: 54946.128 | Z13: 76245.978 | AA13: 111052.25 | AB13: 151507.75 | AD13: 68343.266 | AE13: 78513.605 | AF13: 104101.61
D14: ENR | E14: ='Input - ENR'!O9 -> 112136.8 | F14: ='Input - ENR'!AA9 -> 150480.17 | G14: ='Input - ENR'!AM9 -> 193146.81 | I14: ='MOM Summary'!BM39 -> 86930.596 | J14: ='MOM Summary'!BN39 -> 92702.224 | K14: ='MOM Summary'!BO39 -> 143181.26 | M14: 30645.169 | N14: 39398.285 | O14: 38275.721 | P14: 41260.274 | Q14: 59276.646 | Z14: 89826.036 | AA14: 125498.39 | AB14: 162285.83 | AD14: 65255.747 | AE14: 77975.775 | AF14: 121832.96
D15: ECL BS | E15: ='ECL BS'!O4+'ECL BS'!O10 -> 1839.2751 | F15: ='ECL BS'!AA4+'ECL BS'!AA10 -> 2118.7326 | G15: ='ECL BS'!AM4+'ECL BS'!AM10 -> 2463.5771 | I15: ='MOM Summary'!BM33 -> 2264.6395 | J15: ='MOM Summary'!BN33 -> 2389.8474 | K15: ='MOM Summary'!BO33 -> 2511.4424 | M15: 468.565 | N15: =M15+N7 -> 1036.2892 | O15: =N15+O7 -> 2096.6575 | P15: =O15+P7 -> 2432.4216 | Q15: =P15+Q7 -> 1619.632 | Z15: 1801.2291 | AA15: 1875.3977 | AB15: 2306.6005 | AD15: 2177.1358 | AE15: 2282.7531 | AF15: 2418.8035
D16: ECL BS/ENR | E16: =E15/E14 -> 0.016402065 | F16: =F15/F14 -> 0.014079812 | G16: =G15/G14 -> 0.012754946 | I16: =I15/I14 -> 0.026051121 | J16: =J15/J14 -> 0.025779828 | K16: =K15/K14 -> 0.017540301 | M16: =M15/M14 -> 0.015290012 | N16: =N15/N14 -> 0.026302901 | O16: =O15/O14 -> 0.054777738 | P16: =P15/P14 -> 0.058953112 | Q16: =Q15/Q14 -> 0.027323274 | Z16: 0.020052417 | AA16: 0.014943599 | AB16: 0.014213197 | AD16: 0.033363128 | AE16: 0.029275158 | AF16: 0.019853442
D17: GWO/ANR | E17: =E4/E13 -> 0.005269368 | F17: =F4/F13 -> 0.0044920916 | G17: =G4/G13 -> 0.0042054399 | I17: =I4/I13 -> 0.0058282534 | J17: =J4/J13 -> 0.0076208615 | K17: =K4/K13 -> 0.0073736928 | M17: =M4/M13 -> 0.013045195 | N17: =N4/N13 -> 0.011273948 | O17: =O4/O13 -> 0.021175239 | P17: =P4/P13 -> 0.010733877 | Q17: =Q4/Q13 -> 0.032705812 | Z17: 0.0069697789 | AA17: 0.0090560418 | AB17: 0.0051231564 | AD17: 0.0077757128 | AE17: 0.0148434 | AF17: 0.0085971392
D18: GNPA | E18: ='Input - GNPA'!O39 -> 2313.1767 | F18: ='Input - GNPA'!AA39 -> 2608.9877 | G18: ='Input - GNPA'!AM39 -> 2951.5247 | I18: ='MOM Summary'!BM51 -> 3094.7105 | J18: ='MOM Summary'!BN51 -> 3456.5928 | K18: ='MOM Summary'!BO51 -> 3396.9269 | Z18: 2454.5056 | AA18: 2365.779 | AB18: 2532.1747 | AD18: 3076.6082 | AE18: 3581.3979 | AF18: 3011.2394
D19: NNPA | E19: ='Input - GNPA'!O45 -> 1502.8707 | F19: ='Input - GNPA'!AA45 -> 1735.1589 | G19: ='Input - GNPA'!AM45 -> 1999.6398 | I19: ='MOM Summary'!BM57 -> 1851.8092 | J19: ='MOM Summary'!BN57 -> 2118.8827 | K19: ='MOM Summary'!BO57 -> 2104.6887 | Z19: 1591.3023 | AA19: 1684.8803 | AB19: 1760.2332 | AD19: 1740.778 | AE19: 2240.9527 | AF19: 1888.9856
D20: GNPA% | E20: ='Input - GNPA'!O51 -> 0.020403727 | F20: ='Input - GNPA'!AA51 -> 0.01714911 | G20: ='Input - GNPA'!AM51 -> 0.015114985 | I20: ='MOM Summary'!BM63 -> 0.035715322 | J20: ='MOM Summary'!BN63 -> 0.037408138 | K20: ='MOM Summary'!BO63 -> 0.023801644 | M20: 0.020678312 | N20: 0.036817477 | O20: 0.056028682 | P20: 0.062302654 | Q20: 0.037431908 | R20: 0.069741801 | S20: 0.092798823 | T20: 0.051739469 | U20: =I20/E20 -> 1.7504313 | V20: =J20/F20 -> 2.1813457 | W20: =K20/G20 -> 1.5747051 | Z20: 0.027027797 | AA20: 0.018645964 | AB20: 0.015389441 | AD20: 0.04668013 | AE20: 0.045474874 | AF20: 0.024471418
D21: NNPA% | E21: ='Input - GNPA'!O57 -> 0.01335173 | F21: ='Input - GNPA'!AA57 -> 0.011471243 | G21: ='Input - GNPA'!AM57 -> 0.010290472 | I21: ='MOM Summary'!BM69 -> 0.021573257 | J21: ='MOM Summary'!BN69 -> 0.02313496 | K21: ='MOM Summary'!BO69 -> 0.01487465 | M21: 0.012300268 | N21: 0.019536555 | O21: 0.028748404 | P21: 0.030408628 | Q21: 0.023407939 | R21: 0.046627375 | S21: 0.066861049 | T21: 0.037048977 | U21: =(U18-U19)+(U18*5%) -> 0 | Z21: 0.017790838 | AA21: 0.013233197 | AB21: 0.010967345 | AD21: 0.02641212 | AE21: 0.028454543 | AF21: 0.015351205
D22: Stage1 | E22: ='Calculation - Stage dist'!R35 -> 0.96630674 | F22: ='Calculation - Stage dist'!AD35 -> 0.97136969 | G22: ='Calculation - Stage dist'!AP35 -> 0.97418117 | I22: ='Calculation - Stage dist'!R40 -> 0.94261888 | J22: ='Calculation - Stage dist'!AD40 -> 0.94048853 | K22: ='Calculation - Stage dist'!AP40 -> 0.96103245 | M22: 0.964 | N22: 0.941 | O22: 0.851 | P22: 0.837 | Q22: 0.94092999 | Z22: 0.95635563 | AA22: 0.96842306 | AB22: 0.96865616 | AD22: 0.92872922 | AE22: 0.93163254 | AF22: 0.95560288
D23: Stage2 | E23: ='Calculation - Stage dist'!R36 -> 0.019326476 | F23: ='Calculation - Stage dist'!AD36 -> 0.017002945 | G23: ='Calculation - Stage dist'!AP36 -> 0.015682762 | I23: ='Calculation - Stage dist'!R41 -> 0.031835921 | J23: ='Calculation - Stage dist'!AD41 -> 0.033200693 | K23: ='Calculation - Stage dist'!AP41 -> 0.022800786 | M23: 0.016 | N23: 0.022 | O23: 0.095 | P23: 0.103 | Q23: 0.036119753 | Z23: 0.028151897 | AA23: 0.022410569 | AB23: 0.023408625 | AD23: 0.041388488 | AE23: 0.040385146 | AF23: 0.029566791
D24: Stage3 | E24: ='Calculation - Stage dist'!R37 -> 0.014366784 | F24: ='Calculation - Stage dist'!AD37 -> 0.011627365 | G24: ='Calculation - Stage dist'!AP37 -> 0.010136072 | I24: ='Calculation - Stage dist'!R42 -> 0.025545196 | J24: ='Calculation - Stage dist'!AD42 -> 0.026310781 | K24: ='Calculation - Stage dist'!AP42 -> 0.016166767 | M24: 0.02 | N24: 0.037 | O24: 0.055 | P24: 0.06 | Q24: 0.022950255 | U24: =I24/E24 -> 1.7780733 | V24: =J24/F24 -> 2.2628327 | W24: =K24/G24 -> 1.5949735 | Z24: 0.015492477 | AA24: 0.0091663698 | AB24: 0.0079352188 | AD24: 0.029882289 | AE24: 0.027982312 | AF24: 0.014830329
E25: =1-E21/E20 -> 0.34562297 | F25: =1-F21/F20 -> 0.33108814 | G25: =1-G21/G20 -> 0.3191874 | I25: =1-I21/I20 -> 0.39596633 | J25: =1-J21/J20 -> 0.38155275 | K25: =1-K21/K20 -> 0.37505788 | S25: =S18-S21 -> -0.066861049 | T25: =T18-T21 -> -0.037048977 | U25: =U18-U21 -> 0 | Z25: 0.34175773 | AA25: 0.29029161 | AB25: 0.28734607 | AD25: 0.43418924 | AE25: 0.3742799 | AF25: 0.37268835
S26: =S21-S17 -> 0.066861049
I27: 1294.8645 | J27: 913.53111 | K27: 662.05612
E28: =E9/E13 -> 0.001640082 | F28: =F9/F13 -> 0.0019439968 | I28: =I9/I13 -> 0.0063351109 | J28: =J9/J13 -> 0.0012476628 | K28: =K9/K13 -> 0.0009647234 | Z28: =Z9/Z13 -> 0.0025223286 | AA28: =AA9/AA13 -> 0.00066787079 | AD28: =AD9/AD13 -> 0.0083142588
I30: =I10-I27 -> -241.38527 | J30: =J10-J27 -> -138.86978 | K30: =K10-K27 -> 253.29828

Sheet MOM Summary
C1: =LOOKUP(C2,'Input-Stress Parameters'!$C$9:$BJ$9,'Input-Stress Parameters'!$C$11:$BJ$11) -> N | D1: =LOOKUP(D2,'Input-Stress Parameters'!$C$9:$BJ$9,'Input-Stress Parameters'!$C$11:$BJ$11) -> SL1 | E1: =LOOKUP(E2,'Input-Stress Parameters'!$C$9:$BJ$9,'Input-Stress Parameters'!$C$11:$BJ$11) -> SL1 | F1: =LOOKUP(F2,'Input-Stress Parameters'!$C$9:$BJ$9,'Input-Stress Parameters'!$C$11:$BJ$11) -> SL1 | G1: =LOOKUP(G2,'Input-Stress Parameters'!$C$9:$BJ$9,'Input-Stress Parameters'!$C$11:$BJ$11) -> SL1 | H1: =LOOKUP(H2,'Input-Stress Parameters'!$C$9:$BJ$9,'Input-Stress Parameters'!$C$11:$BJ$11) -> SL1 | I1: =LOOKUP(I2,'Input-Stress Parameters'!$C$9:$BJ$9,'Input-Stress Parameters'!$C$11:$BJ$11) -> SL1 | J1: =LOOKUP(J2,'Input-Stress Parameters'!$C$9:$BJ$9,'Input-Stress Parameters'!$C$11:$BJ$11) -> SL2 | ... BJ1: =LOOKUP(BJ2,'Input-Stress Parameters'!$C$9:$BJ$9,'Input-Stress Parameters'!$C$11:$BJ$11) -> N | BM1: ABP Stress
A2: GWO (Stress) | B2: Inputs | C2: ='Input-Stress Parameters'!C9 -> 45352 | D2: =EDATE(C2,1) -> 45383 | E2: =EDATE(D2,1) -> 45413 | F2: =EDATE(E2,1) -> 45444 | G2: =EDATE(F2,1) -> 45474 | H2: =EDATE(G2,1) -> 45505 | I2: =EDATE(H2,1) -> 45536 | J2: =EDATE(I2,1) -> 45566 | K2: =EDATE(J2,1) -> 45597 | ... BJ2: =EDATE(BI2,1) -> 47150 | BM2: FY24 | BN2: FY25 | BO2: FY26
A3: =$A$2 -> GWO (Stress) | B3: SMHFC | C3: =SUM(C4:C6) -> 66.317611 | D3: =SUM(D4:D6) -> 58.280029 | E3: =SUM(E4:E6) -> 33.734083 | F3: =SUM(F4:F6) -> 39.460786 | G3: =SUM(G4:G6) -> 37.144067 | H3: =SUM(H4:H6) -> 38.522038 | I3: =SUM(I4:I6) -> 31.964472 | J3: =SUM(J4:J6) -> 50.814669 | ... BJ3: =SUM(BJ4:BJ6) -> 0 | BM3: =SUM(BM4:BM6) -> 548.34973 | BN3: =SUM(BN4:BN6) -> 764.78404 | BO3: =SUM(BO4:BO6) -> 929.38938
A4: =$A$2 -> GWO (Stress) | B4: HL | C4: ='Calculation - NCL and ECL'!E25 -> 27.583752 | D4: ='Calculation - NCL and ECL'!F25 -> 41.364333 | E4: ='Calculation - NCL and ECL'!G25 -> 16.61273 | F4: ='Calculation - NCL and ECL'!H25 -> 22.733168 | G4: ='Calculation - NCL and ECL'!I25 -> 17.815778 | H4: ='Calculation - NCL and ECL'!J25 -> 21.977915 | I4: ='Calculation - NCL and ECL'!K25 -> 15.819071 | J4: ='Calculation - NCL and ECL'!L25 -> 29.975829 | ... AM4: ='Calculation - NCL and ECL'!AO25 -> 47.199753 | BM4: =SUM(D4:O4) -> 267.24392 | BN4: =SUM(P4:AA4) -> 480.05523 | BO4: =SUM(AB4:AM4) -> 648.17867
A5: =$A$2 -> GWO (Stress) | B5: LAP | C5: ='Calculation - NCL and ECL'!E26 -> 38.733859 | D5: ='Calculation - NCL and ECL'!F26 -> 16.915696 | E5: ='Calculation - NCL and ECL'!G26 -> 17.121354 | F5: ='Calculation - NCL and ECL'!H26 -> 16.727618 | G5: ='Calculation - NCL and ECL'!I26 -> 19.328289 | H5: ='Calculation - NCL and ECL'!J26 -> 16.544124 | I5: ='Calculation - NCL and ECL'!K26 -> 16.145401 | J5: ='Calculation - NCL and ECL'!L26 -> 20.83884 | ... AM5: ='Calculation - NCL and ECL'!AO26 -> 20.416041 | BM5: =SUM(D5:O5) -> 281.10581 | BN5: =SUM(P5:AA5) -> 284.72881 | BO5: =SUM(AB5:AM5) -> 281.21071
A6: =$A$2 -> GWO (Stress) | B6: DF | C6: ='Calculation - NCL and ECL'!E27 -> 0 | D6: ='Calculation - NCL and ECL'!F27 -> 0 | E6: ='Calculation - NCL and ECL'!G27 -> 0 | F6: ='Calculation - NCL and ECL'!H27 -> 0 | G6: ='Calculation - NCL and ECL'!I27 -> 0 | H6: ='Calculation - NCL and ECL'!J27 -> 0 | I6: ='Calculation - NCL and ECL'!K27 -> 0 | J6: ='Calculation - NCL and ECL'!L27 -> 0 | ... AM6: ='Calculation - NCL and ECL'!AO27 -> 0 | BM6: =SUM(D6:O6) -> 0 | BN6: =SUM(P6:AA6) -> 0 | BO6: =SUM(AB6:AM6) -> 0
A8: Recovery (Stress) | B8: Inputs | C8: =C2 -> 45352 | D8: =EDATE(C8,1) -> 45383 | E8: =EDATE(D8,1) -> 45413 | F8: =EDATE(E8,1) -> 45444 | G8: =EDATE(F8,1) -> 45474 | H8: =EDATE(G8,1) -> 45505 | I8: =EDATE(H8,1) -> 45536 | J8: =EDATE(I8,1) -> 45566 | K8: =EDATE(J8,1) -> 45597 | ... BJ8: =EDATE(BI8,1) -> 47150 | BM8: =BM2 -> FY24 | BN8: =BN2 -> FY25 | BO8: =BO2 -> FY26
A9: =$A$8 -> Recovery (Stress) | B9: SMHFC | C9: =SUM(C10:C12) -> 0 | D9: =SUM(D10:D12) -> 6.5699547 | E9: =SUM(E10:E12) -> 7.7444647 | F9: =SUM(F10:F12) -> 8.4426556 | G9: =SUM(G10:G12) -> 7.0648273 | H9: =SUM(H10:H12) -> 5.5511866 | I9: =SUM(I10:I12) -> 5.5447484 | J9: =SUM(J10:J12) -> 7.1814032 | ... BJ9: =SUM(BJ10:BJ12) -> 0 | BM9: =SUM(BM10:BM12) -> 90.907807 | BN9: =SUM(BN10:BN12) -> 115.33068 | BO9: =SUM(BO10:BO12) -> 135.62991
A10: =$A$8 -> Recovery (Stress) | B10: HL | C10: ='Calculation - NCL and ECL'!E28 -> 0 | D10: ='Calculation - NCL and ECL'!F28 -> 4.5369999 | E10: ='Calculation - NCL and ECL'!G28 -> 5.2758892 | F10: ='Calculation - NCL and ECL'!H28 -> 5.7267373 | G10: ='Calculation - NCL and ECL'!I28 -> 4.8491776 | H10: ='Calculation - NCL and ECL'!J28 -> 3.836753 | I10: ='Calculation - NCL and ECL'!K28 -> 3.8099655 | J10: ='Calculation - NCL and ECL'!L28 -> 4.854774 | ... AM10: ='Calculation - NCL and ECL'!AO28 -> 9.0975916 | BM10: =SUM(D10:O10) -> 60.539428 | BN10: =SUM(P10:AA10) -> 65.808495 | BO10: =SUM(AB10:AM10) -> 82.194201
A11: =$A$8 -> Recovery (Stress) | B11: LAP | C11: ='Calculation - NCL and ECL'!E29 -> 0 | D11: ='Calculation - NCL and ECL'!F29 -> 2.0329549 | E11: ='Calculation - NCL and ECL'!G29 -> 2.4685755 | F11: ='Calculation - NCL and ECL'!H29 -> 2.7159184 | G11: ='Calculation - NCL and ECL'!I29 -> 2.2156497 | H11: ='Calculation - NCL and ECL'!J29 -> 1.7144336 | I11: ='Calculation - NCL and ECL'!K29 -> 1.7347828 | J11: ='Calculation - NCL and ECL'!L29 -> 2.3266292 | ... AM11: ='Calculation - NCL and ECL'!AO29 -> 5.4399638 | BM11: =SUM(D11:O11) -> 30.368378 | BN11: =SUM(P11:AA11) -> 49.522184 | BO11: =SUM(AB11:AM11) -> 53.435711
A12: =$A$8 -> Recovery (Stress) | B12: DF | C12: ='Calculation - NCL and ECL'!E30 -> 0 | D12: ='Calculation - NCL and ECL'!F30 -> 0 | E12: ='Calculation - NCL and ECL'!G30 -> 0 | F12: ='Calculation - NCL and ECL'!H30 -> 0 | G12: ='Calculation - NCL and ECL'!I30 -> 0 | H12: ='Calculation - NCL and ECL'!J30 -> 0 | I12: ='Calculation - NCL and ECL'!K30 -> 0 | J12: ='Calculation - NCL and ECL'!L30 -> 0 | ... AM12: ='Calculation - NCL and ECL'!AO30 -> 0 | BM12: =SUM(D12:O12) -> 0 | BN12: =SUM(P12:AA12) -> 0 | BO12: =SUM(AB12:AM12) -> 0
A14: Model ECL (Stress) | B14: Inputs | C14: =C2 -> 45352 | D14: =EDATE(C14,1) -> 45383 | E14: =EDATE(D14,1) -> 45413 | F14: =EDATE(E14,1) -> 45444 | G14: =EDATE(F14,1) -> 45474 | H14: =EDATE(G14,1) -> 45505 | I14: =EDATE(H14,1) -> 45536 | J14: =EDATE(I14,1) -> 45566 | K14: =EDATE(J14,1) -> 45597 | ... BJ14: =EDATE(BI14,1) -> 47150 | BM14: =BM8 -> FY24 | BN14: =BN8 -> FY25 | BO14: =BO8 -> FY26
A15: =A14 -> Model ECL (Stress) | B15: SMHFC | C15: =SUM(C16:C18) -> -3.4131772 | D15: =SUM(D16:D18) -> 56.977991 | E15: =SUM(E16:E18) -> 53.291542 | F15: =SUM(F16:F18) -> 58.327149 | G15: =SUM(G16:G18) -> 56.37601 | H15: =SUM(H16:H18) -> 55.001484 | I15: =SUM(I16:I18) -> 6.3742211 | J15: =SUM(J16:J18) -> 58.421872 | ... BJ15: =SUM(BJ16:BJ18) -> 0 | BM15: =SUM(BM16:BM18) -> 468.63553 | BN15: =SUM(BN16:BN18) -> 153.07826 | BO15: =SUM(BO16:BO18) -> 150.69271
A16: =A15 -> Model ECL (Stress) | B16: HL | C16: ='Calculation - NCL and ECL'!E22 -> 12.24177 | D16: ='Calculation - NCL and ECL'!F22 -> 26.191163 | E16: ='Calculation - NCL and ECL'!G22 -> 32.177183 | F16: ='Calculation - NCL and ECL'!H22 -> 31.334479 | G16: ='Calculation - NCL and ECL'!I22 -> 29.810836 | H16: ='Calculation - NCL and ECL'!J22 -> 31.031067 | I16: ='Calculation - NCL and ECL'!K22 -> 32.328561 | J16: ='Calculation - NCL and ECL'!L22 -> 33.186034 | ... AM16: ='Calculation - NCL and ECL'!AO22 -> 16.937631 | BM16: =SUM(D16:O16) -> 380.42408 | BN16: =SUM(P16:AA16) -> 144.78224 | BO16: =SUM(AB16:AM16) -> 82.927908
A17: =A16 -> Model ECL (Stress) | B17: LAP | C17: ='Calculation - NCL and ECL'!E23 -> -17.918123 | D17: ='Calculation - NCL and ECL'!F23 -> 31.278298 | E17: ='Calculation - NCL and ECL'!G23 -> 23.893866 | F17: ='Calculation - NCL and ECL'!H23 -> 29.560409 | G17: ='Calculation - NCL and ECL'!I23 -> 28.872835 | H17: ='Calculation - NCL and ECL'!J23 -> 26.075922 | I17: ='Calculation - NCL and ECL'!K23 -> -23.981502 | J17: ='Calculation - NCL and ECL'!L23 -> 27.233429 | ... AM17: ='Calculation - NCL and ECL'!AO23 -> 21.035297 | BM17: =SUM(D17:O17) -> 111.88639 | BN17: =SUM(P17:AA17) -> 20.687978 | BO17: =SUM(AB17:AM17) -> 10.467159
A18: =A17 -> Model ECL (Stress) | B18: DF | C18: ='Calculation - NCL and ECL'!E24 -> 2.2631753 | D18: ='Calculation - NCL and ECL'!F24 -> -0.49147059 | E18: ='Calculation - NCL and ECL'!G24 -> -2.7795071 | F18: ='Calculation - NCL and ECL'!H24 -> -2.5677393 | G18: ='Calculation - NCL and ECL'!I24 -> -2.3076602 | H18: ='Calculation - NCL and ECL'!J24 -> -2.1055049 | I18: ='Calculation - NCL and ECL'!K24 -> -1.9728373 | J18: ='Calculation - NCL and ECL'!L24 -> -1.9975911 | ... AM18: ='Calculation - NCL and ECL'!AO24 -> 9.9277804 | BM18: =SUM(D18:O18) -> -23.67494 | BN18: =SUM(P18:AA18) -> -12.391961 | BO18: =SUM(AB18:AM18) -> 57.29764
A20: Overlay (Stress) | B20: Inputs | C20: =C14 -> 45352 | D20: =EDATE(C20,1) -> 45383 | E20: =EDATE(D20,1) -> 45413 | F20: =EDATE(E20,1) -> 45444 | G20: =EDATE(F20,1) -> 45474 | H20: =EDATE(G20,1) -> 45505 | I20: =EDATE(H20,1) -> 45536 | J20: =EDATE(I20,1) -> 45566 | K20: =EDATE(J20,1) -> 45597 | ... BJ20: =EDATE(BI20,1) -> 47150 | BM20: =BM14 -> FY24 | BN20: =BN14 -> FY25 | BO20: =BO14 -> FY26
A21: =A20 -> Overlay (Stress) | B21: SMHFC | C21: =SUM(C22:C24) -> -4.3338134 | D21: =SUM(D22:D24) -> -5.1007068 | E21: =SUM(E22:E24) -> -1.5665816 | F21: =SUM(F22:F24) -> -1.4301741 | G21: =SUM(G22:G24) -> -0.65208373 | H21: =SUM(H22:H24) -> -2.7817298 | I21: =SUM(I22:I24) -> -2.3709063 | J21: =SUM(J22:J24) -> 114.26704 | ... BJ21: =SUM(BJ22:BJ24) -> 0 | BM21: =SUM(BM22:BM24) -> 127.40175 | BN21: =SUM(BN22:BN24) -> -27.870289 | BO21: =SUM(BO22:BO24) -> -29.097773
A22: =A21 -> Overlay (Stress) | B22: HL | C22: ='Calculation - NCL and ECL'!E37+'Calculation - NCL and ECL'!E40 -> -1 | D22: ='Calculation - NCL and ECL'!F37+'Calculation - NCL and ECL'!F40 -> -5.3353083 | E22: ='Calculation - NCL and ECL'!G37+'Calculation - NCL and ECL'!G40 -> -0.20400505 | F22: ='Calculation - NCL and ECL'!H37+'Calculation - NCL and ECL'!H40 -> -1.3312835 | G22: ='Calculation - NCL and ECL'!I37+'Calculation - NCL and ECL'!I40 -> -0.47259535 | H22: ='Calculation - NCL and ECL'!J37+'Calculation - NCL and ECL'!J40 -> -1.7460392 | I22: ='Calculation - NCL and ECL'!K37+'Calculation - NCL and ECL'!K40 -> -1.5158346 | J22: ='Calculation - NCL and ECL'!L37+'Calculation - NCL and ECL'!L40 -> 68.771536 | ... AM22: ='Calculation - NCL and ECL'!AO37+'Calculation - NCL and ECL'!AO40 -> 0.69058364 | BM22: =SUM(D22:O22) -> 89.160292 | BN22: =SUM(P22:AA22) -> -7.0906116 | BO22: =SUM(AB22:AM22) -> -18.875964
A23: =A22 -> Overlay (Stress) | B23: LAP | C23: ='Calculation - NCL and ECL'!E38+'Calculation - NCL and ECL'!E41 -> -3.3338134 | D23: ='Calculation - NCL and ECL'!F38+'Calculation - NCL and ECL'!F41 -> 0.2346015 | E23: ='Calculation - NCL and ECL'!G38+'Calculation - NCL and ECL'!G41 -> -1.3625766 | F23: ='Calculation - NCL and ECL'!H38+'Calculation - NCL and ECL'!H41 -> -0.098890666 | G23: ='Calculation - NCL and ECL'!I38+'Calculation - NCL and ECL'!I41 -> -0.17948837 | H23: ='Calculation - NCL and ECL'!J38+'Calculation - NCL and ECL'!J41 -> -1.0356907 | I23: ='Calculation - NCL and ECL'!K38+'Calculation - NCL and ECL'!K41 -> -0.85507178 | J23: ='Calculation - NCL and ECL'!L38+'Calculation - NCL and ECL'!L41 -> 45.495502 | ... AM23: ='Calculation - NCL and ECL'!AO38+'Calculation - NCL and ECL'!AO41 -> 1.0647865 | BM23: =SUM(D23:O23) -> 38.241459 | BN23: =SUM(P23:AA23) -> -20.779677 | BO23: =SUM(AB23:AM23) -> -10.221809
A24: =A23 -> Overlay (Stress) | B24: DF | C24: ='Calculation - NCL and ECL'!E39+'Calculation - NCL and ECL'!E42 -> 0 | D24: ='Calculation - NCL and ECL'!F39+'Calculation - NCL and ECL'!F42 -> 0 | E24: ='Calculation - NCL and ECL'!G39+'Calculation - NCL and ECL'!G42 -> 0 | F24: ='Calculation - NCL and ECL'!H39+'Calculation - NCL and ECL'!H42 -> 0 | G24: ='Calculation - NCL and ECL'!I39+'Calculation - NCL and ECL'!I42 -> 0 | H24: ='Calculation - NCL and ECL'!J39+'Calculation - NCL and ECL'!J42 -> 0 | I24: ='Calculation - NCL and ECL'!K39+'Calculation - NCL and ECL'!K42 -> 0 | J24: ='Calculation - NCL and ECL'!L39+'Calculation - NCL and ECL'!L42 -> 0 | ... AM24: ='Calculation - NCL and ECL'!AO39+'Calculation - NCL and ECL'!AO42 -> 0 | BM24: =SUM(D24:O24) -> 0 | BN24: =SUM(P24:AA24) -> 0 | BO24: =SUM(AB24:AM24) -> 0
A26: COC (Stress) | B26: Inputs | C26: =C20 -> 45352 | D26: =EDATE(C26,1) -> 45383 | E26: =EDATE(D26,1) -> 45413 | F26: =EDATE(E26,1) -> 45444 | G26: =EDATE(F26,1) -> 45474 | H26: =EDATE(G26,1) -> 45505 | I26: =EDATE(H26,1) -> 45536 | J26: =EDATE(I26,1) -> 45566 | K26: =EDATE(J26,1) -> 45597 | ... BJ26: =EDATE(BI26,1) -> 47150 | BM26: =BM20 -> FY24 | BN26: =BN20 -> FY25 | BO26: =BO20 -> FY26
A27: =A26 -> COC (Stress) | B27: SMHFC | C27: =SUM(C28:C30) -> 58.57062 | D27: =SUM(D28:D30) -> 103.58736 | E27: =SUM(E28:E30) -> 77.714579 | F27: =SUM(F28:F30) -> 87.915105 | G27: =SUM(G28:G30) -> 85.803166 | H27: =SUM(H28:H30) -> 85.190606 | I27: =SUM(I28:I30) -> 30.423039 | J27: =SUM(J28:J30) -> 216.32218 | ... BJ27: =SUM(BJ28:BJ30) -> 0 | BM27: =SUM(BM28:BM30) -> 1053.4792 | BN27: =SUM(BN28:BN30) -> 774.66133 | BO27: =SUM(BO28:BO30) -> 915.35441
A28: =A27 -> COC (Stress) | B28: HL | C28: =C4-C10+C16+C22 -> 38.825522 | D28: =D4-D10+D16+D22 -> 57.683189 | E28: =E4-E10+E16+E22 -> 43.310018 | F28: =F4-F10+F16+F22 -> 47.009626 | G28: =G4-G10+G16+G22 -> 42.304841 | H28: =H4-H10+H16+H22 -> 47.426189 | I28: =I4-I10+I16+I22 -> 42.821832 | J28: =J4-J10+J16+J22 -> 127.07862 | ... AM28: =AM4-AM10+AM16+AM22 -> 55.730376 | BM28: =SUM(D28:O28) -> 676.28887 | BN28: =SUM(P28:AA28) -> 551.93837 | BO28: =SUM(AB28:AM28) -> 630.03642
A29: =A28 -> COC (Stress) | B29: LAP | C29: =C5-C11+C17+C23 -> 17.481922 | D29: =D5-D11+D17+D23 -> 46.39564 | E29: =E5-E11+E17+E23 -> 37.184068 | F29: =F5-F11+F17+F23 -> 43.473218 | G29: =G5-G11+G17+G23 -> 45.805986 | H29: =H5-H11+H17+H23 -> 39.869922 | I29: =I5-I11+I17+I23 -> -10.425956 | J29: =J5-J11+J17+J23 -> 91.241142 | ... AM29: =AM5-AM11+AM17+AM23 -> 37.07616 | BM29: =SUM(D29:O29) -> 400.86528 | BN29: =SUM(P29:AA29) -> 235.11493 | BO29: =SUM(AB29:AM29) -> 228.02035
A30: =A29 -> COC (Stress) | B30: DF | C30: =C6-C12+C18+C24 -> 2.2631753 | D30: =D6-D12+D18+D24 -> -0.49147059 | E30: =E6-E12+E18+E24 -> -2.7795071 | F30: =F6-F12+F18+F24 -> -2.5677393 | G30: =G6-G12+G18+G24 -> -2.3076602 | H30: =H6-H12+H18+H24 -> -2.1055049 | I30: =I6-I12+I18+I24 -> -1.9728373 | J30: =J6-J12+J18+J24 -> -1.9975911 | ... AM30: =AM6-AM12+AM18+AM24 -> 9.9277804 | BM30: =SUM(D30:O30) -> -23.67494 | BN30: =SUM(P30:AA30) -> -12.391961 | BO30: =SUM(AB30:AM30) -> 57.29764
A32: ECL BS (Stress) | B32: Inputs | C32: =C26 -> 45352 | D32: =EDATE(C32,1) -> 45383 | E32: =EDATE(D32,1) -> 45413 | F32: =EDATE(E32,1) -> 45444 | G32: =EDATE(F32,1) -> 45474 | H32: =EDATE(G32,1) -> 45505 | I32: =EDATE(H32,1) -> 45536 | J32: =EDATE(I32,1) -> 45566 | K32: =EDATE(J32,1) -> 45597 | ... BJ32: =EDATE(BI32,1) -> 47150 | BM32: =BM26 -> FY24 | BN32: =BN26 -> FY25 | BO32: =BO26 -> FY26
A33: =A32 -> ECL BS (Stress) | B33: SMHFC | C33: =SUM(C34:C36) -> 1668.6022 | D33: =SUM(D34:D36) -> 1720.4795 | E33: =SUM(E34:E36) -> 1772.2044 | F33: =SUM(F34:F36) -> 1829.1014 | G33: =SUM(G34:G36) -> 1884.8253 | H33: =SUM(H34:H36) -> 1937.0451 | I33: =SUM(I34:I36) -> 1941.0484 | J33: =SUM(J34:J36) -> 2113.7373 | ... BJ33: =SUM(BJ34:BJ36) -> 0 | BM33: =SUM(BM34:BM36) -> 2264.6395 | BN33: =SUM(BN34:BN36) -> 2389.8474 | BO33: =SUM(BO34:BO36) -> 2511.4424
A34: =A33 -> ECL BS (Stress) | B34: HL | C34: ='ECL BS'!C17+'ECL BS'!C23+'ECL BS'!C29 -> 1021.0778 | D34: ='ECL BS'!D17+'ECL BS'!D23+'ECL BS'!D29 -> 1041.9336 | E34: ='ECL BS'!E17+'ECL BS'!E23+'ECL BS'!E29 -> 1073.9068 | F34: ='ECL BS'!F17+'ECL BS'!F23+'ECL BS'!F29 -> 1103.91 | G34: ='ECL BS'!G17+'ECL BS'!G23+'ECL BS'!G29 -> 1133.2482 | H34: ='ECL BS'!H17+'ECL BS'!H23+'ECL BS'!H29 -> 1162.5333 | I34: ='ECL BS'!I17+'ECL BS'!I23+'ECL BS'!I29 -> 1193.346 | J34: ='ECL BS'!J17+'ECL BS'!J23+'ECL BS'!J29 -> 1295.3036 | ... AM34: ='ECL BS'!AM17+'ECL BS'!AM23+'ECL BS'!AM29 -> 1692.4057 | BM34: =O34 -> 1490.6621 | BN34: =AA34 -> 1628.3538 | BO34: =AM34 -> 1692.4057
A35: =A34 -> ECL BS (Stress) | B35: LAP | C35: ='ECL BS'!C18+'ECL BS'!C24+'ECL BS'!C30 -> 564.43113 | D35: ='ECL BS'!D18+'ECL BS'!D24+'ECL BS'!D30 -> 595.94403 | E35: ='ECL BS'!E18+'ECL BS'!E24+'ECL BS'!E30 -> 618.47532 | F35: ='ECL BS'!F18+'ECL BS'!F24+'ECL BS'!F30 -> 647.93684 | G35: ='ECL BS'!G18+'ECL BS'!G24+'ECL BS'!G30 -> 676.63018 | H35: ='ECL BS'!H18+'ECL BS'!H24+'ECL BS'!H30 -> 701.67041 | I35: ='ECL BS'!I18+'ECL BS'!I24+'ECL BS'!I30 -> 676.83384 | J35: ='ECL BS'!J18+'ECL BS'!J24+'ECL BS'!J30 -> 749.56277 | ... AM35: ='ECL BS'!AM18+'ECL BS'!AM24+'ECL BS'!AM30 -> 714.71263 | BM35: =O35 -> 714.55898 | BN35: =AA35 -> 714.46728 | BO35: =AM35 -> 714.71263
A36: =A35 -> ECL BS (Stress) | B36: DF | C36: ='ECL BS'!C19+'ECL BS'!C25+'ECL BS'!C31 -> 83.093289 | D36: ='ECL BS'!D19+'ECL BS'!D25+'ECL BS'!D31 -> 82.601818 | E36: ='ECL BS'!E19+'ECL BS'!E25+'ECL BS'!E31 -> 79.822311 | F36: ='ECL BS'!F19+'ECL BS'!F25+'ECL BS'!F31 -> 77.254572 | G36: ='ECL BS'!G19+'ECL BS'!G25+'ECL BS'!G31 -> 74.946912 | H36: ='ECL BS'!H19+'ECL BS'!H25+'ECL BS'!H31 -> 72.841407 | I36: ='ECL BS'!I19+'ECL BS'!I25+'ECL BS'!I31 -> 70.86857 | J36: ='ECL BS'!J19+'ECL BS'!J25+'ECL BS'!J31 -> 68.870979 | ... AM36: ='ECL BS'!AM19+'ECL BS'!AM25+'ECL BS'!AM31 -> 104.32403 | BM36: =O36 -> 59.418349 | BN36: =AA36 -> 47.026388 | BO36: =AM36 -> 104.32403
A38: ENR (Stress) | B38: Inputs | C38: =C32 -> 45352 | D38: =EDATE(C38,1) -> 45383 | E38: =EDATE(D38,1) -> 45413 | F38: =EDATE(E38,1) -> 45444 | G38: =EDATE(F38,1) -> 45474 | H38: =EDATE(G38,1) -> 45505 | I38: =EDATE(H38,1) -> 45536 | J38: =EDATE(I38,1) -> 45566 | K38: =EDATE(J38,1) -> 45597 | ... BJ38: =EDATE(BI38,1) -> 47150 | BM38: =BM32 -> FY24 | BN38: =BN32 -> FY25 | BO38: =BO32 -> FY26
A39: =A38 -> ENR (Stress) | B39: SMHFC | C39: =SUM(C40:C42) -> 78777.342 | D39: =SUM(D40:D42) -> 80016.05 | E39: =SUM(E40:E42) -> 81263.959 | F39: =SUM(F40:F42) -> 82589.784 | G39: =SUM(G40:G42) -> 83962.455 | H39: =SUM(H40:H42) -> 85453.725 | I39: =SUM(I40:I42) -> 85079.435 | J39: =SUM(J40:J42) -> 86182.149 | ... BJ39: =SUM(BJ40:BJ42) -> 0 | BM39: =SUM(BM40:BM42) -> 86930.596 | BN39: =SUM(BN40:BN42) -> 92702.224 | BO39: =SUM(BO40:BO42) -> 143181.26
A40: =A39 -> ENR (Stress) | B40: HL | C40: ='Input - ENR'!C16 -> 52026.136 | D40: ='Input - ENR'!D16 -> 52427.211 | E40: ='Input - ENR'!E16 -> 53343.308 | F40: ='Input - ENR'!F16 -> 54301.817 | G40: ='Input - ENR'!G16 -> 55283.254 | H40: ='Input - ENR'!H16 -> 56336.702 | I40: ='Input - ENR'!I16 -> 57443.134 | J40: ='Input - ENR'!J16 -> 58210.554 | ... AM40: ='Input - ENR'!AM16 -> 102687.74 | BM40: =O40 -> 62701.13 | BN40: =AA40 -> 69324.804 | BO40: =AM40 -> 102687.74
A41: =A40 -> ENR (Stress) | B41: LAP | C41: ='Input - ENR'!C17 -> 19204.152 | D41: ='Input - ENR'!D17 -> 20089.604 | E41: ='Input - ENR'!E17 -> 20678.004 | F41: ='Input - ENR'!F17 -> 21279.43 | G41: ='Input - ENR'!G17 -> 21876.99 | H41: ='Input - ENR'!H17 -> 22499.638 | I41: ='Input - ENR'!I17 -> 21190.748 | J41: ='Input - ENR'!J17 -> 21699.963 | ... AM41: ='Input - ENR'!AM17 -> 30668.49 | BM41: =O41 -> 18786.779 | BN41: =AA41 -> 19064.451 | BO41: =AM41 -> 30668.49
A42: =A41 -> ENR (Stress) | B42: DF | C42: ='Input - ENR'!C18 -> 7547.0548 | D42: ='Input - ENR'!D18 -> 7499.2351 | E42: ='Input - ENR'!E18 -> 7242.6473 | F42: ='Input - ENR'!F18 -> 7008.5371 | G42: ='Input - ENR'!G18 -> 6802.2111 | H42: ='Input - ENR'!H18 -> 6617.3849 | I42: ='Input - ENR'!I18 -> 6445.553 | J42: ='Input - ENR'!J18 -> 6271.6308 | ... AM42: ='Input - ENR'!AM18 -> 9825.028 | BM42: =O42 -> 5442.6873 | BN42: =AA42 -> 4312.9699 | BO42: =AM42 -> 9825.028
A44: ANR (Stress) | B44: Inputs | C44: =C38 -> 45352 | D44: =EDATE(C44,1) -> 45383 | E44: =EDATE(D44,1) -> 45413 | F44: =EDATE(E44,1) -> 45444 | G44: =EDATE(F44,1) -> 45474 | H44: =EDATE(G44,1) -> 45505 | I44: =EDATE(H44,1) -> 45536 | J44: =EDATE(I44,1) -> 45566 | K44: =EDATE(J44,1) -> 45597 | ... BJ44: =EDATE(BI44,1) -> 47150 | BM44: =BM38 -> FY24 | BN44: =BN38 -> FY25 | BO44: =BO38 -> FY26
A45: =A44 -> ANR (Stress) | B45: SMHFC | C45: =SUM(C46:C48) -> 86554.433 | D45: =SUM(D46:D48) -> 88358.894 | E45: =SUM(E46:E48) -> 89259.1 | F45: =SUM(F46:F48) -> 90235.884 | G45: =SUM(G46:G48) -> 91333.291 | H45: =SUM(H46:H48) -> 92447.995 | I45: =SUM(I46:I48) -> 93762.196 | J45: =SUM(J46:J48) -> 94797.18 | ... BJ45: =SUM(BJ46:BJ48) -> 0 | BM45: =SUM(BM46:BM48) -> 94084.743 | BN45: =SUM(BN46:BN48) -> 100354.01 | BO45: =SUM(BO46:BO48) -> 126041.24
A46: =A45 -> ANR (Stress) | B46: HL | C46: ='Input - ANR'!C10 -> 50793.946 | D46: ='Input - ANR'!D10 -> 51905.961 | E46: ='Input - ANR'!E10 -> 52737.653 | F46: ='Input - ANR'!F10 -> 53621.68 | G46: ='Input - ANR'!G10 -> 54568.555 | H46: ='Input - ANR'!H10 -> 55518.816 | I46: ='Input - ANR'!I10 -> 56612.593 | J46: ='Input - ANR'!J10 -> 57504.898 | ... AM46: ='Input - ANR'!AM10 -> 99067.598 | BM46: =AVERAGE(D46:O46) -> 56912.186 | BN46: =AVERAGE(P46:AA46) -> 63303.718 | BO46: =AVERAGE(AB46:AM46) -> 80722.958
A47: =A46 -> ANR (Stress) | B47: LAP | C47: ='Input - ANR'!C11 -> 28570.328 | D47: ='Input - ANR'!D11 -> 29172.184 | E47: ='Input - ANR'!E11 -> 29470.946 | F47: ='Input - ANR'!F11 -> 29816.807 | G47: ='Input - ANR'!G11 -> 30192.774 | H47: ='Input - ANR'!H11 -> 30553.85 | I47: ='Input - ANR'!I11 -> 30968.449 | J47: ='Input - ANR'!J11 -> 31296.697 | ... AM47: ='Input - ANR'!AM11 -> 47435.787 | BM47: =AVERAGE(D47:O47) -> 31015.92 | BN47: =AVERAGE(P47:AA47) -> 32878.516 | BO47: =AVERAGE(AB47:AM47) -> 39622.537
...

Sheet Output - CoC
D1: Plan | H1: Stress | L1: Variance
B2: Product | C2: Parameter | D2: SL1 | E2: SL2 | F2: SL3 | H2: SL1 | I2: SL2 | J2: SL3 | L2: SL1 | M2: SL2 | N2: SL3
B3: SMHFC | C3: NCL | D3: =SUM(D7,D11,D15) -> 197.57232 | E3: =SUM(E7,E11,E15) -> 601.9846 | F3: =SUM(F7,F11,F15) -> 542.51289 | H3: =SUM(H7,H11,H15) -> 198.18764 | I3: =SUM(I7,I11,I15) -> 680.59102 | J3: =SUM(J7,J11,J15) -> 733.41637 | L3: =H3-D3 -> 0.61531716 | M3: =I3-E3 -> 78.60642 | N3: =J3-F3 -> 190.90348
B4: =B3 -> SMHFC | C4: ECL | D4: =SUM(D8,D12,D16) -> 124.14199 | E4: =SUM(E8,E12,E16) -> 160.88567 | F4: =SUM(F8,F12,F16) -> 340.22178 | H4: =SUM(H8,H12,H16) -> 272.44621 | I4: =SUM(I8,I12,I16) -> 542.14004 | J4: =SUM(J8,J12,J16) -> -298.04612 | L4: =H4-D4 -> 148.30422 | M4: =I4-E4 -> 381.25437 | N4: =J4-F4 -> -638.2679
B5: =B3 -> SMHFC | C5: CoC | D5: =SUM(D9,D13,D17) -> 321.71431 | E5: =SUM(E9,E13,E17) -> 762.87027 | F5: =SUM(F9,F13,F17) -> 882.73467 | H5: =SUM(H9,H13,H17) -> 470.63385 | I5: =SUM(I9,I13,I17) -> 1222.7311 | J5: =SUM(J9,J13,J17) -> 435.37025 | L5: =H5-D5 -> 148.91954 | M5: =I5-E5 -> 459.86079 | N5: =J5-F5 -> -447.36442
B7: HL | C7: NCL | D7: =SUMIF('Calculation - NCL and ECL'!$E$1:$AN$1,$D$2,'Calculation - NCL and ECL'!$E7:$AN7) -> 107.03862 | E7: =SUMIF('Calculation - NCL and ECL'!$E$1:$AN$1,$E$2,'Calculation - NCL and ECL'!$E7:$AN7) -> 299.21568 | F7: =SUMIF('Calculation - NCL and ECL'!$E$1:$AN$1,$F$2,'Calculation - NCL and ECL'!$E7:$AN7) -> 378.03543 | H7: =SUMIF('Calculation - NCL and ECL'!$E$1:$AN$1,$H$2,'Calculation - NCL and ECL'!$E16:$AN16) -> 108.28747 | I7: =SUMIF('Calculation - NCL and ECL'!$E$1:$AN$1,$I$2,'Calculation - NCL and ECL'!$E16:$AN16) -> 346.0241 | J7: =SUMIF('Calculation - NCL and ECL'!$E$1:$AN$1,$J$2,'Calculation - NCL and ECL'!$E16:$AN16) -> 529.10787 | L7: =H7-D7 -> 1.2488542 | M7: =I7-E7 -> 46.808421 | N7: =J7-F7 -> 151.07244
B8: =B7 -> HL | C8: ECL | D8: =SUMIF('Calculation - NCL and ECL'!$E$1:$AN$1,$D$2,'Calculation - NCL and ECL'!$E19:$AN19)+SUMIF('Calculation - NCL and ECL'!$E$1:$AN$1,$D$2,'Calculation - NCL and ECL'!$E37:$AN37) -> 105.34106 | E8: =SUMIF('Calculation - NCL and ECL'!$E$1:$AN$1,$E$2,'Calculation - NCL and ECL'!$E19:$AN19)+SUMIF('Calculation - NCL and ECL'!$E$1:$AN$1,$E$2,'Calculation - NCL and ECL'!$E37:$AN37) -> 201.29442 | F8: =SUMIF('Calculation - NCL and ECL'!$E$1:$AN$1,$F$2,'Calculation - NCL and ECL'!$E19:$AN19)+SUMIF('Calculation - NCL and ECL'!$E$1:$AN$1,$F$2,'Calculation - NCL and ECL'!$E37:$AN37) -> 277.89183 | H8: =SUMIF('Calculation - NCL and ECL'!$E$1:$AN$1,$H$2,'Calculation - NCL and ECL'!$E22:$AN22)+SUMIF('Calculation - NCL and ECL'!$E$1:$AN$1,$H$2,'Calculation - NCL and ECL'!$E37:$AN37) -> 172.26822 | I8: =SUMIF('Calculation - NCL and ECL'!$E$1:$AN$1,$E$2,'Calculation - NCL and ECL'!$E22:$AN22)+SUMIF('Calculation - NCL and ECL'!$E$1:$AN$1,$E$2,'Calculation - NCL and ECL'!$E37:$AN37) -> 389.62508 | J8: =SUMIF('Calculation - NCL and ECL'!$E$1:$AN$1,$F$2,'Calculation - NCL and ECL'!$E22:$AN22)+SUMIF('Calculation - NCL and ECL'!$E$1:$AN$1,$F$2,'Calculation - NCL and ECL'!$E37:$AN37) -> -130.82361 | L8: =H8-D8 -> 66.927163 | M8: =I8-E8 -> 188.33067 | N8: =J8-F8 -> -408.71543
B9: =B7 -> HL | C9: CoC | D9: =SUM(D7:D8) -> 212.37968 | E9: =SUM(E7:E8) -> 500.5101 | F9: =SUM(F7:F8) -> 655.92726 | H9: =SUM(H7:H8) -> 280.55569 | I9: =SUM(I7:I8) -> 735.64919 | J9: =SUM(J7:J8) -> 398.28427 | L9: =H9-D9 -> 68.176017 | M9: =I9-E9 -> 235.13909 | N9: =J9-F9 -> -257.64299
B11: LAP | C11: NCL | D11: =SUMIF('Calculation - NCL and ECL'!$E$1:$AN$1,$D$2,'Calculation - NCL and ECL'!$E8:$AN8) -> 90.533704 | E11: =SUMIF('Calculation - NCL and ECL'!$E$1:$AN$1,$E$2,'Calculation - NCL and ECL'!$E8:$AN8) -> 302.76892 | F11: =SUMIF('Calculation - NCL and ECL'!$E$1:$AN$1,$F$2,'Calculation - NCL and ECL'!$E8:$AN8) -> 164.47746 | H11: =SUMIF('Calculation - NCL and ECL'!$E$1:$AN$1,$H$2,'Calculation - NCL and ECL'!$E17:$AN17) -> 89.900167 | I11: =SUMIF('Calculation - NCL and ECL'!$E$1:$AN$1,$I$2,'Calculation - NCL and ECL'!$E17:$AN17) -> 334.56692 | J11: =SUMIF('Calculation - NCL and ECL'!$E$1:$AN$1,$J$2,'Calculation - NCL and ECL'!$E17:$AN17) -> 204.3085 | L11: =H11-D11 -> -0.63353703 | M11: =I11-E11 -> 31.797999 | N11: =J11-F11 -> 39.831036
B12: =B11 -> LAP | C12: ECL | D12: =SUMIF('Calculation - NCL and ECL'!$E$1:$AN$1,$D$2,'Calculation - NCL and ECL'!$E20:$AN20)+SUMIF('Calculation - NCL and ECL'!$E$1:$AN$1,$D$2,'Calculation - NCL and ECL'!$E38:$AN38) -> 12.445883 | E12: =SUMIF('Calculation - NCL and ECL'!$E$1:$AN$1,$E$2,'Calculation - NCL and ECL'!$E20:$AN20)+SUMIF('Calculation - NCL and ECL'!$E$1:$AN$1,$E$2,'Calculation - NCL and ECL'!$E38:$AN38) -> -63.456252 | F12: =SUMIF('Calculation - NCL and ECL'!$E$1:$AN$1,$F$2,'Calculation - NCL and ECL'!$E20:$AN20)+SUMIF('Calculation - NCL and ECL'!$E$1:$AN$1,$F$2,'Calculation - NCL and ECL'!$E38:$AN38) -> 41.42075 | H12: =SUMIF('Calculation - NCL and ECL'!$E$1:$AN$1,$H$2,'Calculation - NCL and ECL'!$E23:$AN23)+SUMIF('Calculation - NCL and ECL'!$E$1:$AN$1,$H$2,'Calculation - NCL and ECL'!$E38:$AN38) -> 112.40271 | I12: =SUMIF('Calculation - NCL and ECL'!$E$1:$AN$1,$E$2,'Calculation - NCL and ECL'!$E23:$AN23)+SUMIF('Calculation - NCL and ECL'!$E$1:$AN$1,$E$2,'Calculation - NCL and ECL'!$E38:$AN38) -> 177.45645 | J12: =SUMIF('Calculation - NCL and ECL'!$E$1:$AN$1,$F$2,'Calculation - NCL and ECL'!$E23:$AN23)+SUMIF('Calculation - NCL and ECL'!$E$1:$AN$1,$F$2,'Calculation - NCL and ECL'!$E38:$AN38) -> -178.9301 | L12: =H12-D12 -> 99.956829 | M12: =I12-E12 -> 240.9127 | N12: =J12-F12 -> -220.35085
B13: =B11 -> LAP | C13: CoC | D13: =SUM(D11:D12) -> 102.97959 | E13: =SUM(E11:E12) -> 239.31267 | F13: =SUM(F11:F12) -> 205.89821 | H13: =SUM(H11:H12) -> 202.30288 | I13: =SUM(I11:I12) -> 512.02336 | J13: =SUM(J11:J12) -> 25.378405 | L13: =H13-D13 -> 99.323292 | M13: =I13-E13 -> 272.7107 | N13: =J13-F13 -> -180.51981
B15: DF | C15: NCL | D15: =SUMIF('Calculation - NCL and ECL'!$E$1:$AN$1,$D$2,'Calculation - NCL and ECL'!$E9:$AN9) -> 0 | E15: =SUMIF('Calculation - NCL and ECL'!$E$1:$AN$1,$E$2,'Calculation - NCL and ECL'!$E9:$AN9) -> 0 | F15: =SUMIF('Calculation - NCL and ECL'!$E$1:$AN$1,$F$2,'Calculation - NCL and ECL'!$E9:$AN9) -> 0 | H15: =IFERROR(SUMIF('Calculation - NCL and ECL'!$E$1:$AN$1,$H$2,'Calculation - NCL and ECL'!$E18:$AN18),0) -> 0 | I15: =IFERROR(SUMIF('Calculation - NCL and ECL'!$E$1:$AN$1,$H$2,'Calculation - NCL and ECL'!$E18:$AN18),0) -> 0 | J15: =IFERROR(SUMIF('Calculation - NCL and ECL'!$E$1:$AN$1,$H$2,'Calculation - NCL and ECL'!$E18:$AN18),0) -> 0 | L15: =H15-D15 -> 0 | M15: =I15-E15 -> 0 | N15: =J15-F15 -> 0
B16: =B15 -> DF | C16: ECL | D16: =SUMIF('Calculation - NCL and ECL'!$E$1:$AN$1,$D$2,'Calculation - NCL and ECL'!$E21:$AN21)+SUMIF('Calculation - NCL and ECL'!$E$1:$AN$1,$D$2,'Calculation - NCL and ECL'!$E39:$AN39) -> 6.3550475 | E16: =SUMIF('Calculation - NCL and ECL'!$E$1:$AN$1,$E$2,'Calculation - NCL and ECL'!$E21:$AN21)+SUMIF('Calculation - NCL and ECL'!$E$1:$AN$1,$E$2,'Calculation - NCL and ECL'!$E39:$AN39) -> 23.047506 | F16: =SUMIF('Calculation - NCL and ECL'!$E$1:$AN$1,$F$2,'Calculation - NCL and ECL'!$E21:$AN21)+SUMIF('Calculation - NCL and ECL'!$E$1:$AN$1,$F$2,'Calculation - NCL and ECL'!$E39:$AN39) -> 20.9092 | H16: =IFERROR(SUMIF('Calculation - NCL and ECL'!$E$1:$AN$1,$H$2,'Calculation - NCL and ECL'!$E24:$AN24),0)+IFERROR(SUMIF('Calculation - NCL and ECL'!$E$1:$AN$1,$H$2,'Calculation - NCL and ECL'!$E39:$AN39),0) -> -12.224719 | I16: =IFERROR(SUMIF('Calculation - NCL and ECL'!$E$1:$AN$1,$E$2,'Calculation - NCL and ECL'!$E24:$AN24),0)+IFERROR(SUMIF('Calculation - NCL and ECL'!$E$1:$AN$1,$E$2,'Calculation - NCL and ECL'!$E39:$AN39),0) -> -24.94149 | J16: =IFERROR(SUMIF('Calculation - NCL and ECL'!$E$1:$AN$1,$F$2,'Calculation - NCL and ECL'!$E24:$AN24),0)+IFERROR(SUMIF('Calculation - NCL and ECL'!$E$1:$AN$1,$F$2,'Calculation - NCL and ECL'!$E39:$AN39),0) -> 11.707581 | L16: =H16-D16 -> -18.579767 | M16: =I16-E16 -> -47.988995 | N16: =J16-F16 -> -9.201619
B17: =B15 -> DF | C17: CoC | D17: =SUM(D15:D16) -> 6.3550475 | E17: =SUM(E15:E16) -> 23.047506 | F17: =SUM(F15:F16) -> 20.9092 | H17: =SUM(H15:H16) -> -12.224719 | I17: =SUM(I15:I16) -> -24.94149 | J17: =SUM(J15:J16) -> 11.707581 | L17: =H17-D17 -> -18.579767 | M17: =I17-E17 -> -47.988995 | N17: =J17-F17 -> -9.201619

Sheet Input-Stress Parameters
B1: Back - Index | T1: `
B2: Plan Start Month>> | C2: 45352
B3: Stress Start Month>> | C3: 45383
B4: Stress Levels | C4: SL1 | D4: SL2 | E4: SL3 | K4: BOM | L4: EOM
C5: 7 | D5: 25 | E5: 5 | G5: Slowdown | H5: SL1 Duration (in months) | J5: 6 | K5: =C3 -> 45383 | L5: =EDATE(K5,(J5-1)) -> 45536
G6: Recession | H6: SL2 Duration (in months) | J6: 12 | K6: =EDATE(L5,1) -> 45566 | L6: =EDATE(K6,(J6-1)) -> 45901
G7: Recovery | H7: SL3 Duration (in months) | J7: 12 | K7: =EDATE(L6,1) -> 45931 | L7: =EDATE(K7,(J7-1)) -> 46266
B8: =EOMONTH(TODAY(),-1)+1 -> 45444
B9: Parameters | C9: =C2 -> 45352 | D9: =EDATE(C9,1) -> 45383 | E9: =EDATE(D9,1) -> 45413 | F9: =EDATE(E9,1) -> 45444 | G9: =EDATE(F9,1) -> 45474 | H9: =EDATE(G9,1) -> 45505 | I9: =EDATE(H9,1) -> 45536 | J9: =EDATE(I9,1) -> 45566 | K9: =EDATE(J9,1) -> 45597 | ... BJ9: =EDATE(BI9,1) -> 47150
B10: Stress Level | C10: =IF(C9<$K$5,1,IF(C9>$L$5,IF(C9>$L$6,IF(C9>$L$7,1,$E$5),$D$5),$C$5)) -> 1 | D10: =IF(D9<$K$5,1,IF(D9>$L$5,IF(D9>$L$6,IF(D9>$L$7,1,$E$5),$D$5),$C$5)) -> 7 | E10: =IF(E9<$K$5,1,IF(E9>$L$5,IF(E9>$L$6,IF(E9>$L$7,1,$E$5),$D$5),$C$5)) -> 7 | F10: =IF(F9<$K$5,1,IF(F9>$L$5,IF(F9>$L$6,IF(F9>$L$7,1,$E$5),$D$5),$C$5)) -> 7 | G10: =IF(G9<$K$5,1,IF(G9>$L$5,IF(G9>$L$6,IF(G9>$L$7,1,$E$5),$D$5),$C$5)) -> 7 | H10: =IF(H9<$K$5,1,IF(H9>$L$5,IF(H9>$L$6,IF(H9>$L$7,1,$E$5),$D$5),$C$5)) -> 7 | I10: =IF(I9<$K$5,1,IF(I9>$L$5,IF(I9>$L$6,IF(I9>$L$7,1,$E$5),$D$5),$C$5)) -> 7 | J10: =IF(J9<$K$5,1,IF(J9>$L$5,IF(J9>$L$6,IF(J9>$L$7,1,$E$5),$D$5),$C$5)) -> 25 | ... BJ10: =IF(BJ9<$K$5,1,IF(BJ9>$L$5,IF(BJ9>$L$6,IF(BJ9>$L$7,1,$E$5),$D$5),$C$5)) -> 1
B11: Stress stage | C11: =IF(C10=$C$5,$C$4,IF(C10=$D$5,$D$4,IF(C10=$E$5,$E$4,"N"))) -> N | D11: =IF(D10=$C$5,$C$4,IF(D10=$D$5,$D$4,IF(D10=$E$5,$E$4,"N"))) -> SL1 | E11: =IF(E10=$C$5,$C$4,IF(E10=$D$5,$D$4,IF(E10=$E$5,$E$4,"N"))) -> SL1 | F11: =IF(F10=$C$5,$C$4,IF(F10=$D$5,$D$4,IF(F10=$E$5,$E$4,"N"))) -> SL1 | G11: =IF(G10=$C$5,$C$4,IF(G10=$D$5,$D$4,IF(G10=$E$5,$E$4,"N"))) -> SL1 | H11: =IF(H10=$C$5,$C$4,IF(H10=$D$5,$D$4,IF(H10=$E$5,$E$4,"N"))) -> SL1 | I11: =IF(I10=$C$5,$C$4,IF(I10=$D$5,$D$4,IF(I10=$E$5,$E$4,"N"))) -> SL1 | J11: =IF(J10=$C$5,$C$4,IF(J10=$D$5,$D$4,IF(J10=$E$5,$E$4,"N"))) -> SL2 | ... BJ11: =IF(BJ10=$C$5,$C$4,IF(BJ10=$D$5,$D$4,IF(BJ10=$E$5,$E$4,"N"))) -> N
B12: Stress tag | C12: =IF(C11="N",C11,IF(C9>$B$17,"SL4P",IF(C9>$B$16,"SL3P",IF(C9>$B$15,"SL2P","SL1P")))) -> N | D12: =IF(D11="N",D11,IF(D9>$B$17,"SL4P",IF(D9>$B$16,"SL3P",IF(D9>$B$15,"SL2P","SL1P")))) -> SL1P | E12: =IF(E11="N",E11,IF(E9>$B$17,"SL4P",IF(E9>$B$16,"SL3P",IF(E9>$B$15,"SL2P","SL1P")))) -> SL1P | F12: =IF(F11="N",F11,IF(F9>$B$17,"SL4P",IF(F9>$B$16,"SL3P",IF(F9>$B$15,"SL2P","SL1P")))) -> SL1P | G12: =IF(G11="N",G11,IF(G9>$B$17,"SL4P",IF(G9>$B$16,"SL3P",IF(G9>$B$15,"SL2P","SL1P")))) -> SL1P | H12: =IF(H11="N",H11,IF(H9>$B$17,"SL4P",IF(H9>$B$16,"SL3P",IF(H9>$B$15,"SL2P","SL1P")))) -> SL1P | I12: =IF(I11="N",I11,IF(I9>$B$17,"SL4P",IF(I9>$B$16,"SL3P",IF(I9>$B$15,"SL2P","SL1P")))) -> SL1P | J12: =IF(J11="N",J11,IF(J9>$B$17,"SL4P",IF(J9>$B$16,"SL3P",IF(J9>$B$15,"SL2P","SL1P")))) -> SL2P | ... Z12: =IF(Z11="N",Z11,IF(Z9>$B$17,"SL4P",IF(Z9>$B$16,"SL3P",IF(Z9>$B$15,"SL2P","SL1P")))) -> SL4P | AA12: =IF(AA11="N",AA11,IF(AA9>$B$19,"SL4P",IF(AA9>$B$16,"SL3P",IF(AA9>$B$15,"SL2P","SL1P")))) -> SL3P | AB12: =IF(AB11="N",AB11,IF(AB9>$B$19,"SL4P",IF(AB9>$B$16,"SL3P",IF(AB9>$B$15,"SL2P","SL1P")))) -> SL3P | AC12: =IF(AC11="N",AC11,IF(AC9>$B$19,"SL4P",IF(AC9>$B$16,"SL3P",IF(AC9>$B$15,"SL2P","SL1P")))) -> SL3P | AD12: =IF(AD11="N",AD11,IF(AD9>$B$19,"SL4P",IF(AD9>$B$16,"SL3P",IF(AD9>$B$15,"SL2P","SL1P")))) -> SL3P | AE12: =IF(AE11="N",AE11,IF(AE9>$B$19,"SL4P",IF(AE9>$B$16,"SL3P",IF(AE9>$B$15,"SL2P","SL1P")))) -> SL3P | AF12: =IF(AF11="N",AF11,IF(AF9>$B$19,"SL4P",IF(AF9>$B$16,"SL3P",IF(AF9>$B$15,"SL2P","SL1P")))) -> SL3P | AG12: =IF(AG11="N",AG11,IF(AG9>$B$19,"SL4P",IF(AG9>$B$16,"SL3P",IF(AG9>$B$15,"SL2P","SL1P")))) -> SL3P | AH12: =IF(AH11="N",AH11,IF(AH9>$B$19,"SL4P",IF(AH9>$B$16,"SL3P",IF(AH9>$B$15,"SL2P","SL1P")))) -> N | ... AL12: =IF(AL11="N",AL11,IF(AL9>$B$19,"SL4P",IF(AL9>$B$16,"SL3P",IF(AL9>$B$15,"SL2P","SL1P")))) -> N | AM12: =IF(AM11="N",AM11,IF(AM9>$B$17,"SL4P",IF(AM9>$B$16,"SL3P",IF(AM9>$B$15,"SL2P","SL1P")))) -> N | AN12: =IF(AN11="N",AN11,IF(AN9>$B$17,"SL4P",IF(AN9>$B$16,"SL3P",IF(AN9>$B$15,"SL2P","SL1P")))) -> N | AO12: =IF(AO11="N",AO11,IF(AO9>$B$17,"SL4P",IF(AO9>$B$16,"SL3P",IF(AO9>$B$15,"SL2P","SL1P")))) -> N | AP12: =IF(AP11="N",AP11,IF(AP9>$B$17,"SL4P",IF(AP9>$B$16,"SL3P",IF(AP9>$B$15,"SL2P","SL1P")))) -> N | AQ12: =IF(AQ11="N",AQ11,IF(AQ9>$B$17,"SL4P",IF(AQ9>$B$16,"SL3P",IF(AQ9>$B$15,"SL2P","SL1P")))) -> N | AR12: =IF(AR11="N",AR11,IF(AR9>$B$17,"SL4P",IF(AR9>$B$16,"SL3P",IF(AR9>$B$15,"SL2P","SL1P")))) -> N | AS12: =IF(AS11="N",AS11,IF(AS9>$B$17,"SL4P",IF(AS9>$B$16,"SL3P",IF(AS9>$B$15,"SL2P","SL1P")))) -> N | AT12: =IF(AT11="N",AT11,IF(AT9>$B$17,"SL4P",IF(AT9>$B$16,"SL3P",IF(AT9>$B$15,"SL2P","SL1P")))) -> N | ... BJ12: =IF(BJ11="N",BJ11,IF(BJ9>$B$17,"SL4P",IF(BJ9>$B$16,"SL3P",IF(BJ9>$B$15,"SL2P","SL1P")))) -> N
F14: 1 | G14: =F14+1 -> 2 | H14: =G14+1 -> 3 | I14: =H14+1 -> 4 | J14: =I14+1 -> 5 | K14: =J14+1 -> 6 | L14: =K14+1 -> 7 | M14: =L14+1 -> 8 | N14: =M14+1 -> 9 | ... AC14: =AB14+1 -> 24
B15: =EDATE(K5,(D15-1)) -> 45536 | C15: SL1P | D15: 6
B16: =EDATE(K5,(D16-1)) -> 45901 | C16: SL2P | D16: 18 | E16: =D16-D15 -> 12
B17: =EDATE(K5,(D17-1)) -> 45992 | C17: SL3P | D17: 21 | E17: =D17-D16 -> 3
B18: Secured | E18: =SUM(J5:J7)-D17 -> 9
B19: =EDATE(K5,(D19-1)) -> 46631 | C19: SL3P | D19: 42 | E19: 24
D20: =_xlfn.IFNA(VLOOKUP(D9,$B$15:$C$17,2,),D11) -> SL1
B24: Recovery | C24: SL31 Duration (in months) | E24: =J7/2 -> 6 | F24: =K7 -> 45931 | G24: =EDATE(F24,(E24-1)) -> 46082 | H24: SL31
B25: Recovery | C25: SL32 Duration (in months) | E25: =J7/2 -> 6 | F25: =EDATE(G24,1) -> 46113 | G25: =EDATE(F25,(E25-1)) -> 46266 | H25: SL32
B27: Parameters | C27: =C2 -> 45352 | D27: =EDATE(C27,1) -> 45383 | E27: =EDATE(D27,1) -> 45413 | F27: =EDATE(E27,1) -> 45444 | G27: =EDATE(F27,1) -> 45474 | H27: =EDATE(G27,1) -> 45505 | I27: =EDATE(H27,1) -> 45536 | J27: =EDATE(I27,1) -> 45566 | K27: =EDATE(J27,1) -> 45597 | ... BJ27: =EDATE(BI27,1) -> 47150
B28: Stress stage | C28: =IF(C27>=$F$24,IF(C27<=$G$24,$H$24,IF(C27>=$F$25,IF(C27<=$G$25,$H$25,C11))),C11) -> N | D28: =IF(D27>=$F$24,IF(D27<=$G$24,$H$24,IF(D27>=$F$25,IF(D27<=$G$25,$H$25,D11))),D11) -> SL1 | E28: =IF(E27>=$F$24,IF(E27<=$G$24,$H$24,IF(E27>=$F$25,IF(E27<=$G$25,$H$25,E11))),E11) -> SL1 | F28: =IF(F27>=$F$24,IF(F27<=$G$24,$H$24,IF(F27>=$F$25,IF(F27<=$G$25,$H$25,F11))),F11) -> SL1 | G28: =IF(G27>=$F$24,IF(G27<=$G$24,$H$24,IF(G27>=$F$25,IF(G27<=$G$25,$H$25,G11))),G11) -> SL1 | H28: =IF(H27>=$F$24,IF(H27<=$G$24,$H$24,IF(H27>=$F$25,IF(H27<=$G$25,$H$25,H11))),H11) -> SL1 | I28: =IF(I27>=$F$24,IF(I27<=$G$24,$H$24,IF(I27>=$F$25,IF(I27<=$G$25,$H$25,I11))),I11) -> SL1 | J28: =IF(J27>=$F$24,IF(J27<=$G$24,$H$24,IF(J27>=$F$25,IF(J27<=$G$25,$H$25,J11))),J11) -> SL2 | ... BJ28: =IF(BJ27>=$F$24,IF(BJ27<=$G$24,$H$24,IF(BJ27>=$F$25,IF(BJ27<=$G$25,$H$25,BJ11))),BJ11) -> N

Sheet Input - Disbursals
A1: Back - Index | C1: =LOOKUP(C2,'Input-Stress Parameters'!$C$9:$BJ$9,'Input-Stress Parameters'!$C$11:$BJ$11) -> N | D1: =LOOKUP(D2,'Input-Stress Parameters'!$C$9:$BJ$9,'Input-Stress Parameters'!$C$11:$BJ$11) -> SL1 | E1: =LOOKUP(E2,'Input-Stress Parameters'!$C$9:$BJ$9,'Input-Stress Parameters'!$C$11:$BJ$11) -> SL1 | F1: =LOOKUP(F2,'Input-Stress Parameters'!$C$9:$BJ$9,'Input-Stress Parameters'!$C$11:$BJ$11) -> SL1 | G1: =LOOKUP(G2,'Input-Stress Parameters'!$C$9:$BJ$9,'Input-Stress Parameters'!$C$11:$BJ$11) -> SL1 | H1: =LOOKUP(H2,'Input-Stress Parameters'!$C$9:$BJ$9,'Input-Stress Parameters'!$C$11:$BJ$11) -> SL1 | I1: =LOOKUP(I2,'Input-Stress Parameters'!$C$9:$BJ$9,'Input-Stress Parameters'!$C$11:$BJ$11) -> SL1 | J1: =LOOKUP(J2,'Input-Stress Parameters'!$C$9:$BJ$9,'Input-Stress Parameters'!$C$11:$BJ$11) -> SL2 | ... BJ1: =LOOKUP(BJ2,'Input-Stress Parameters'!$C$9:$BJ$9,'Input-Stress Parameters'!$C$11:$BJ$11) -> N
A2: Disbursals - Stress | B2: Inputs | C2: ='Input-Stress Parameters'!C9 -> 45352 | D2: =EDATE(C2,1) -> 45383 | E2: =EDATE(D2,1) -> 45413 | F2: =EDATE(E2,1) -> 45444 | G2: =EDATE(F2,1) -> 45474 | H2: =EDATE(G2,1) -> 45505 | I2: =EDATE(H2,1) -> 45536 | J2: =EDATE(I2,1) -> 45566 | K2: =EDATE(J2,1) -> 45597 | ... BJ2: =EDATE(BI2,1) -> 47150
A3: Disbursals - Stress | B3: SMHFC | C3: =SUM(C4:C6) -> 4986.6667 | D3: =SUM(D4:D6) -> 2255 | E3: =SUM(E4:E6) -> 2402.5 | F3: =SUM(F4:F6) -> 2494 | G3: =SUM(G4:G6) -> 2550.65 | H3: =SUM(H4:H6) -> 2688 | I3: =SUM(I4:I6) -> 2780.125 | J3: =SUM(J4:J6) -> 2540 | ... BJ3: =SUM(BJ4:BJ6) -> 0
