Workbook

Sheet HFT Ref Data
A2: Indian Governments | B2: Maturity | C2: Sub Type | D2: Risk charge % of exposure
A3: Central & State Govt Securities | B3: All | C3: 1A | D3: 0
A4: Approved Securities guaranteed by CG | B4: All | C4: 2A | D4: 0
A5: Approved Securities guaranteed by SG | B5: <= 6months | C5: 3A | D5: 0.0028
B6: >6m, <=24m | C6: 4A | D6: 0.0113
B7: >24m | C7: 5A | D7: 0.018
A9: Foregin Central Governments
A10: AAA to AA | B10: All | C10: 1B | D10: 0
A11: A to BBB | B11: <= 6months | C11: 2B | D11: 0.0028
B12: >6m, <=24m | C12: 3B | D12: 0.0113
B13: >24m | C13: 4B | D13: 0.018
A14: BB to B | B14: All | C14: 5B | D14: 0.09
A15: Below B | B15: All | C15: 6B | D15: 0.135
A16: Unrated | B16: All | C16: 7B | D16: 0.135
A18: Bank Bonds
A19: Scheduled Banks - Capital Instruments
A20: CET1+CCB above applicable minimum | B20: <= 6months | C20: 1C | D20: 0.0175
B21: >6m, <=24m | C21: 2C | D21: 0.0706
B22: >24m | C22: 3C | D22: 0.1125
A23: Min CET1+ CCB btn 75% to 100% of min CCB | B23: All | C23: 4C | D23: 0.135
A24: Min CET1+ CCB btn 50% to 75% of min CCB | B24: All | C24: 5C | D24: 0.225
A25: Min CET1+ CCB btn 0% to 50% of min CCB | B25: All | C25: 6C | D25: 0.315
A26: less than min CET1 | B26: All | C26: 7C | D26: 0.5625
A28: Scheduled Banks - Other Instruments
A29: CET1+CCB above applicable minimum | B29: <= 6months | C29: 1D | D29: 0.0028
B30: >6m, <=24m | C30: 2D | D30: 0.0113
B31: >24m | C31: 3D | D31: 0.018
A32: Min CET1+ CCB btn 75% to 100% of min CCB | B32: All | C32: 4D | D32: 0.045
A33: Min CET1+ CCB btn 50% to 75% of min CCB | B33: All | C33: 5D | D33: 0.09
A34: Min CET1+ CCB btn 0% to 50% of min CCB | B34: All | C34: 6D | D34: 0.135
A35: less than min CET1 | B35: All | C35: 7D | D35: 0.5625
A38: Non-Scheduled Banks: Capital Instruments
A39: CET1+CCB above applicable minimum | B39: <= 6months | C39: 1E | D39: 0.0175
B40: >6m, <=24m | C40: 2E | D40: 0.0706
B41: >24m | C41: 3E | D41: 0.1125
A42: Min CET1+ CCB btn 75% to 100% of min CCB | B42: All | C42: 4E | D42: 0.225
A43: Min CET1+ CCB btn 50% to 75% of min CCB | B43: All | C43: 5E | D43: 0.315
A44: Min CET1+ CCB btn 0% to 50% of min CCB | B44: All | C44: 6E | D44: 0.5625
A45: less than min CET1 | B45: All | C45: 7E | D45: 1
A47: Non-Scheduled Banks - Other Instruments
...

Sheet AFS Ref Data
A2: Indian Governments | B2: Maturity | C2: Sub Type | D2: Risk charge % of exposure
A3: Central & State Govt Securities | B3: All | C3: 1A | D3: 0
A4: Approved Securities guaranteed by CG | B4: All | C4: 2A | D4: 0
A5: Approved Securities guaranteed by SG | B5: All | C5: 3A | D5: 0.018
A7: Foregin Central Governments
A8: AAA to AA | B8: All | C8: 1B | D8: 0
A9: A | B9: All | C9: 2B | D9: 0.018
A10: BBB | B10: All | C10: 3B | D10: 0.045
A11: BB to B | B11: All | C11: 4B | D11: 0.09
A12: Below B | B12: All | C12: 5B | D12: 0.135
A13: Unrated | B13: All | C13: 6B | D13: 0.09
A15: Bank Bonds
A16: Scheduled Banks - Capital Instruments
A17: CET1+CCB above applicable minimum | B17: All | C17: 1C | D17: 0.1125
A18: Min CET1+ CCB btn 75% to 100% of min CCB | B18: All | C18: 2C | D18: 0.135
A19: Min CET1+ CCB btn 50% to 75% of min CCB | B19: All | C19: 3C | D19: 0.225
A20: Min CET1+ CCB btn 0% to 50% of min CCB | B20: All | C20: 4C | D20: 0.315
A21: less than min CET1 | B21: All | C21: 5C | D21: 0.5625
A23: Scheduled Banks - Other Instruments
A24: CET1+CCB above applicable minimum | B24: All | C24: 1D | D24: 0.018
A25: Min CET1+ CCB btn 75% to 100% of min CCB | B25: All | C25: 2D | D25: 0.045
A26: Min CET1+ CCB btn 50% to 75% of min CCB | B26: All | C26: 3D | D26: 0.09
A27: Min CET1+ CCB btn 0% to 50% of min CCB | B27: All | C27: 4D | D27: 0.135
A28: less than min CET1 | B28: All | C28: 5D | D28: 0.5625
A31: Non-Scheduled Banks: Capital Instruments
A32: CET1+CCB above applicable minimum | B32: All | C32: 1E | D32: 0.1125
A33: Min CET1+ CCB btn 75% to 100% of min CCB | B33: All | C33: 2E | D33: 0.225
A34: Min CET1+ CCB btn 50% to 75% of min CCB | B34: All | C34: 3E | D34: 0.315
A35: Min CET1+ CCB btn 0% to 50% of min CCB | B35: All | C35: 4E | D35: 0.5625
A36: less than min CET1 | B36: All | C36: 5E | D36: 1
A38: Non-Scheduled Banks - Other Instruments
A39: CET1+CCB above applicable minimum | B39: <= 6months | C39: 1F | D39: 0.1125
A40: Min CET1+ CCB btn 75% to 100% of min CCB | B40: All | C40: 2F | D40: 0.135
A41: Min CET1+ CCB btn 50% to 75% of min CCB | B41: All | C41: 3F | D41: 0.225
A42: Min CET1+ CCB btn 0% to 50% of min CCB | B42: All | C42: 4F | D42: 0.315
A43: less than min CET1 | B43: All | C43: 5F | D43: 0.5625
A45: Corporate Bonds
A46: AAA | B46: All | C46: 1G | D46: 0.018
A47: AA | B47: All | C47: 2G | D47: 0.027
A48: A | B48: All | C48: 3G | D48: 0.045
...

Sheet Zone Identifier
B2: Maturity | D2: Assumed Yield change | E2: Zones
B3: 1 month or less | C3: 1 | D3: 0.01 | E3: Zone1
B4: 1 to 3 months | C4: 3 | D4: 0.01 | E4: Zone1
B5: 3 to 6 months | C5: 6 | D5: 0.01 | E5: Zone1
B6: 6 to 12 months | C6: 12 | D6: 0.01 | E6: Zone1
B7: 1 to 1.9 years | C7: 22 | D7: 0.009 | E7: Zone2
B8: 1.9 to 2.8 years | C8: 33 | D8: 0.008 | E8: Zone2
B9: 2.8 to 3.6 years | C9: 43 | D9: 0.0075 | E9: Zone2
B10: 3.6 to 4.3 years | C10: 52 | D10: 0.0075 | E10: Zone3
B11: 4.3 to 5.7 years | C11: 68 | D11: 0.007 | E11: Zone3
B12: 5.7 to 7.3 years | C12: 87 | D12: 0.0065 | E12: Zone3
B13: 7.3 to 9.3 years | C13: 111 | D13: 0.006 | E13: Zone3
B14: 9.3 to 10.6 years | C14: 127 | D14: 0.006 | E14: Zone3
B15: 10.6 to 12 years | C15: =12*12 -> 144 | D15: 0.006 | E15: Zone3
B16: 12 to 20 years | C16: =12*20 -> 240 | D16: 0.006 | E16: Zone3
B17: Over 20 years | D17: 0.006 | E17: Zone3

Sheet Portfolio
A1: Instrument ID | B1: Type | C1: Sub-Type | D1: Specific Risk Excluded | E1: Currency | F1: FX Conversion | G1: Rating | H1: Observation Date | I1: Maturity Date | J1: Coupon % | K1: Coupon Frequency | L1: Frequency in Number | M1: Yield % | N1: Market Value (+ve or -ve based on the position) | O1: Position | P1: Zone | Q1: Time Band | R1: Maturity | S1: Mduration | T1: INR MTM | U1: SR Capital Charge % | V1: Capital charge | W1: Assumed Yld change | X1: Adj Delta Value | Y1: Total Specific Capital Charge (Rupee)
A2: 0% INR GOVERNMENT OF INDIA TB 18/04/2024 91 D | B2: AFS | C2: 1A | D2: Y | E2: INR | F2: 1 | H2: 45382 | I2: 45400 | J2: 0 | L2: =IF(K2="Annually",1,IF(K2="Semi-Annually",2,4)) -> 4 | M2: 0.07 | N2: 498219505 | O2: Long | P2: =VLOOKUP(Q2,'Zone Identifier'!$B$3:$E$17,4,FALSE) -> Zone1 | Q2: =IF(R2<=1,"1 month or less",IF(AND(R2>1,R2<=3),"1 to 3 months",IF(AND(R2>3,R2<=6),"3 to 6 months",IF(AND(R2>6,R2<=12),"6 to 12 months",IF(AND(R2>12,R2<=22),"1 to 1.9 years",IF(AND(R2>22,R2<33),"1.9 to 2.8 years",IF(AND(R2>33,R2<=43),"2.8 to 3.6 years",IF(AND(R2>43,R2<=52),"3.6 to 4.3 years",IF(AND(R2>52,R2<=68),"4.3 to 5.7 years",IF(AND(R2>68,R2<=87),"5.7 to 7.3 years",IF(AND(R2>87,R2<=111),"7.3 to 9.3 years",IF(AND(R2>111,R2<=127),"9.3 to 10.6 years",IF(AND(R2>127,R2<=144),"10.6 to 12 years",IF(AND(R2>144,R2<=240),"12 to 20 years",IF(R2>240,"Over 20 years",""))))))))))))))) -> 1 month or less | R2: =(I2-H2)*12/365 -> 0.59178082 | S2: =MDURATION(H2,I2,J2,M2,L2,3) -> 0.049140049 | T2: =N2*F2 -> 498219505 | U2: =IF(B2="HFT",VLOOKUP(C2,'HFT Ref Data'!$C$3:$D$65,2,FALSE),IF(B2 = "AFS",VLOOKUP(C2,'AFS Ref Data'!$C$3:$D$53,2,FALSE),0)) -> 0 | V2: =ABS(N2)*U2 -> 0 | W2: =VLOOKUP(Q2,'Zone Identifier'!$B$3:$E$17,3,FALSE) -> 0.01 | X2: =W2*S2*T2 -> 244825.31 | Y2: =SUMIF(D2:D89,"N",V2:V89) -> 8918582.8
A3: 0% INR GOVERNMENT OF INDIA TB 04/04/2024 364 D | B3: AFS | C3: 1A | D3: Y | E3: INR | F3: 1 | H3: 45382 | I3: 45386 | J3: 0 | L3: =IF(K3="Annually",1,IF(K3="Semi-Annually",2,4)) -> 4 | M3: 0.0693 | N3: 199812396 | O3: Long | P3: =VLOOKUP(Q3,'Zone Identifier'!$B$3:$E$17,4,FALSE) -> Zone1 | Q3: =IF(R3<=1,"1 month or less",IF(AND(R3>1,R3<=3),"1 to 3 months",IF(AND(R3>3,R3<=6),"3 to 6 months",IF(AND(R3>6,R3<=12),"6 to 12 months",IF(AND(R3>12,R3<=22),"1 to 1.9 years",IF(AND(R3>22,R3<33),"1.9 to 2.8 years",IF(AND(R3>33,R3<=43),"2.8 to 3.6 years",IF(AND(R3>43,R3<=52),"3.6 to 4.3 years",IF(AND(R3>52,R3<=68),"4.3 to 5.7 years",IF(AND(R3>68,R3<=87),"5.7 to 7.3 years",IF(AND(R3>87,R3<=111),"7.3 to 9.3 years",IF(AND(R3>111,R3<=127),"9.3 to 10.6 years",IF(AND(R3>127,R3<=144),"10.6 to 12 years",IF(AND(R3>144,R3<=240),"12 to 20 years",IF(R3>240,"Over 20 years",""))))))))))))))) -> 1 month or less | R3: =(I3-H3)*12/365 -> 0.13150685 | S3: =MDURATION(H3,I3,J3,M3,L3,3) -> 0.011445542 | T3: =N3*F3 -> 199812396 | U3: =IF(B3="HFT",VLOOKUP(C3,'HFT Ref Data'!$C$3:$D$65,2,FALSE),IF(B3 = "AFS",VLOOKUP(C3,'AFS Ref Data'!$C$3:$D$53,2,FALSE),0)) -> 0 | V3: =ABS(N3)*U3 -> 0 | W3: =VLOOKUP(Q3,'Zone Identifier'!$B$3:$E$17,3,FALSE) -> 0.01 | X3: =W3*S3*T3 -> 22869.611
A4: 0% INR GOVERNMENT OF INDIA TB 18/04/2024 91 D | B4: AFS | C4: 1A | D4: Y | E4: INR | F4: 1 | H4: 45382 | I4: 45400 | J4: 0 | L4: =IF(K4="Annually",1,IF(K4="Semi-Annually",2,4)) -> 4 | M4: 0.0687 | N4: 697507307 | O4: Long | P4: =VLOOKUP(Q4,'Zone Identifier'!$B$3:$E$17,4,FALSE) -> Zone1 | Q4: =IF(R4<=1,"1 month or less",IF(AND(R4>1,R4<=3),"1 to 3 months",IF(AND(R4>3,R4<=6),"3 to 6 months",IF(AND(R4>6,R4<=12),"6 to 12 months",IF(AND(R4>12,R4<=22),"1 to 1.9 years",IF(AND(R4>22,R4<33),"1.9 to 2.8 years",IF(AND(R4>33,R4<=43),"2.8 to 3.6 years",IF(AND(R4>43,R4<=52),"3.6 to 4.3 years",IF(AND(R4>52,R4<=68),"4.3 to 5.7 years",IF(AND(R4>68,R4<=87),"5.7 to 7.3 years",IF(AND(R4>87,R4<=111),"7.3 to 9.3 years",IF(AND(R4>111,R4<=127),"9.3 to 10.6 years",IF(AND(R4>127,R4<=144),"10.6 to 12 years",IF(AND(R4>144,R4<=240),"12 to 20 years",IF(R4>240,"Over 20 years",""))))))))))))))) -> 1 month or less | R4: =(I4-H4)*12/365 -> 0.59178082 | S4: =MDURATION(H4,I4,J4,M4,L4,3) -> 0.04915575 | T4: =N4*F4 -> 697507307 | U4: =IF(B4="HFT",VLOOKUP(C4,'HFT Ref Data'!$C$3:$D$65,2,FALSE),IF(B4 = "AFS",VLOOKUP(C4,'AFS Ref Data'!$C$3:$D$53,2,FALSE),0)) -> 0 | V4: =ABS(N4)*U4 -> 0 | W4: =VLOOKUP(Q4,'Zone Identifier'!$B$3:$E$17,3,FALSE) -> 0.01 | X4: =W4*S4*T4 -> 342864.95
A5: 0% INR GOVERNMENT OF INDIA TB 25/04/2024 364 D | B5: AFS | C5: 1A | D5: Y | E5: INR | F5: 1 | H5: 45382 | I5: 45407 | J5: 0 | L5: =IF(K5="Annually",1,IF(K5="Semi-Annually",2,4)) -> 4 | M5: 0.0677 | N5: 696590622 | O5: Long | P5: =VLOOKUP(Q5,'Zone Identifier'!$B$3:$E$17,4,FALSE) -> Zone1 | Q5: =IF(R5<=1,"1 month or less",IF(AND(R5>1,R5<=3),"1 to 3 months",IF(AND(R5>3,R5<=6),"3 to 6 months",IF(AND(R5>6,R5<=12),"6 to 12 months",IF(AND(R5>12,R5<=22),"1 to 1.9 years",IF(AND(R5>22,R5<33),"1.9 to 2.8 years",IF(AND(R5>33,R5<=43),"2.8 to 3.6 years",IF(AND(R5>43,R5<=52),"3.6 to 4.3 years",IF(AND(R5>52,R5<=68),"4.3 to 5.7 years",IF(AND(R5>68,R5<=87),"5.7 to 7.3 years",IF(AND(R5>87,R5<=111),"7.3 to 9.3 years",IF(AND(R5>111,R5<=127),"9.3 to 10.6 years",IF(AND(R5>127,R5<=144),"10.6 to 12 years",IF(AND(R5>144,R5<=240),"12 to 20 years",IF(R5>240,"Over 20 years",""))))))))))))))) -> 1 month or less | R5: =(I5-H5)*12/365 -> 0.82191781 | S5: =MDURATION(H5,I5,J5,M5,L5,3) -> 0.06802673 | T5: =N5*F5 -> 696590622 | U5: =IF(B5="HFT",VLOOKUP(C5,'HFT Ref Data'!$C$3:$D$65,2,FALSE),IF(B5 = "AFS",VLOOKUP(C5,'AFS Ref Data'!$C$3:$D$53,2,FALSE),0)) -> 0 | V5: =ABS(N5)*U5 -> 0 | W5: =VLOOKUP(Q5,'Zone Identifier'!$B$3:$E$17,3,FALSE) -> 0.01 | X5: =W5*S5*T5 -> 473867.82
A6: Bank of Baroda | B6: AFS | C6: 1D | D6: N | E6: INR | F6: 1 | H6: 45382 | I6: 45428 | J6: 0 | L6: =IF(K6="Annually",1,IF(K6="Semi-Annually",2,4)) -> 4 | M6: 0.0764 | N6: 4.9547682e+08 | O6: Long | P6: =VLOOKUP(Q6,'Zone Identifier'!$B$3:$E$17,4,FALSE) -> Zone1 | Q6: =IF(R6<=1,"1 month or less",IF(AND(R6>1,R6<=3),"1 to 3 months",IF(AND(R6>3,R6<=6),"3 to 6 months",IF(AND(R6>6,R6<=12),"6 to 12 months",IF(AND(R6>12,R6<=22),"1 to 1.9 years",IF(AND(R6>22,R6<33),"1.9 to 2.8 years",IF(AND(R6>33,R6<=43),"2.8 to 3.6 years",IF(AND(R6>43,R6<=52),"3.6 to 4.3 years",IF(AND(R6>52,R6<=68),"4.3 to 5.7 years",IF(AND(R6>68,R6<=87),"5.7 to 7.3 years",IF(AND(R6>87,R6<=111),"7.3 to 9.3 years",IF(AND(R6>111,R6<=127),"9.3 to 10.6 years",IF(AND(R6>127,R6<=144),"10.6 to 12 years",IF(AND(R6>144,R6<=240),"12 to 20 years",IF(R6>240,"Over 20 years",""))))))))))))))) -> 1 to 3 months | R6: =(I6-H6)*12/365 -> 1.5123288 | S6: =MDURATION(H6,I6,J6,M6,L6,3) -> 0.12702586 | T6: =N6*F6 -> 4.9547682e+08 | U6: =IF(B6="HFT",VLOOKUP(C6,'HFT Ref Data'!$C$3:$D$65,2,FALSE),IF(B6 = "AFS",VLOOKUP(C6,'AFS Ref Data'!$C$3:$D$53,2,FALSE),0)) -> 0.018 | V6: =ABS(N6)*U6 -> 8918582.8 | W6: =VLOOKUP(Q6,'Zone Identifier'!$B$3:$E$17,3,FALSE) -> 0.01 | X6: =W6*S6*T6 -> 629383.7

Sheet Capital Charge
B1: Zone1 | F1: Zone2 | I1: Zone3
A2: TimeBand | B2: 1 month or less | C2: 1 to 3 months | D2: 3 to 6 months | E2: 6 to 12 months | F2: 1 to 1.9 years | G2: 1.9 to 2.8 years | H2: 2.8 to 3.6 years | I2: 3.6 to 4.3 years | J2: 4.3 to 5.7 years | K2: 5.7 to 7.3 years | L2: 7.3 to 9.3 years | M2: 9.3 to 10.6 years | N2: 10.6 to 12 years | O2: 12 to 20 years | P2: Over 20 years | Q2: Grand Total
A4: Position
A5: Long_ | B5: =SUMIFS(Portfolio!$X$2:'Portfolio'!$X$89,Portfolio!$O$2:'Portfolio'!$O$89,"=Long",Portfolio!$P$2:'Portfolio'!$P$89,"=Zone1",Portfolio!$Q$2:$Q$89,"=1 month or less") -> 1084427.7 | C5: =SUMIFS(Portfolio!$X$2:'Portfolio'!$X$89,Portfolio!$O$2:'Portfolio'!$O$89,"=Long",Portfolio!$P$2:'Portfolio'!$P$89,"=Zone1",Portfolio!$Q$2:$Q$89,"=1 to 3 months") -> 629383.7 | D5: =SUMIFS(Portfolio!$X$2:'Portfolio'!$X$89,Portfolio!$O$2:'Portfolio'!$O$89,"=Long",Portfolio!$P$2:'Portfolio'!$P$89,"=Zone1",Portfolio!$Q$2:$Q$89,"=3 to 6 months") -> 0 | E5: =SUMIFS(Portfolio!$X$2:'Portfolio'!$X$89,Portfolio!$O$2:'Portfolio'!$O$89,"=Long",Portfolio!$P$2:'Portfolio'!$P$89,"=Zone1",Portfolio!$Q$2:$Q$89,"=6 to 12 months") -> 0 | F5: =SUMIFS(Portfolio!$X$2:'Portfolio'!$X$89,Portfolio!$O$2:'Portfolio'!$O$89,"=Long",Portfolio!$P$2:'Portfolio'!$P$89,"=Zone2",Portfolio!$Q$2:$Q$89,"=1 to 1.9 years") -> 0 | G5: =SUMIFS(Portfolio!$X$2:'Portfolio'!$X$89,Portfolio!$O$2:'Portfolio'!$O$89,"=Long",Portfolio!$P$2:'Portfolio'!$P$89,"=Zone2",Portfolio!$Q$2:$Q$89,"=1.9 to 2.8 years") -> 0 | H5: =SUMIFS(Portfolio!$X$2:'Portfolio'!$X$89,Portfolio!$O$2:'Portfolio'!$O$89,"=Long",Portfolio!$P$2:'Portfolio'!$P$89,"=Zone2",Portfolio!$Q$2:$Q$89,"=2.8 to 3.6 years") -> 0 | I5: =SUMIFS(Portfolio!$X$2:'Portfolio'!$X$89,Portfolio!$O$2:'Portfolio'!$O$89,"=Long",Portfolio!$P$2:'Portfolio'!$P$89,"=Zone3",Portfolio!$Q$2:$Q$89,"=3.6 to 4.3 years") -> 0 | J5: =SUMIFS(Portfolio!$X$2:'Portfolio'!$X$89,Portfolio!$O$2:'Portfolio'!$O$89,"=Long",Portfolio!$P$2:'Portfolio'!$P$89,"=Zone3",Portfolio!$Q$2:$Q$89,"=4.3 to 5.7 years") -> 0 | K5: =SUMIFS(Portfolio!$X$2:'Portfolio'!$X$89,Portfolio!$O$2:'Portfolio'!$O$89,"=Long",Portfolio!$P$2:'Portfolio'!$P$89,"=Zone3",Portfolio!$Q$2:$Q$89,"=5.7 to 7.3 years") -> 0 | L5: =SUMIFS(Portfolio!$X$2:'Portfolio'!$X$89,Portfolio!$O$2:'Portfolio'!$O$89,"=Long",Portfolio!$P$2:'Portfolio'!$P$89,"=Zone3",Portfolio!$Q$2:$Q$89,"=7.3 to 9.3 years") -> 0 | M5: =SUMIFS(Portfolio!$X$2:'Portfolio'!$X$89,Portfolio!$O$2:'Portfolio'!$O$89,"=Long",Portfolio!$P$2:'Portfolio'!$P$89,"=Zone3",Portfolio!$Q$2:$Q$89,"=9.3 to 10.6 years") -> 0 | N5: =SUMIFS(Portfolio!$X$2:'Portfolio'!$X$89,Portfolio!$O$2:'Portfolio'!$O$89,"=Long",Portfolio!$P$2:'Portfolio'!$P$89,"=Zone3",Portfolio!$Q$2:$Q$89,"=10.6 to 12 years") -> 0 | O5: =SUMIFS(Portfolio!$X$2:'Portfolio'!$X$89,Portfolio!$O$2:'Portfolio'!$O$89,"=Long",Portfolio!$P$2:'Portfolio'!$P$89,"=Zone3",Portfolio!$Q$2:$Q$89,"=12 to 20 years") -> 0 | P5: =SUMIFS(Portfolio!$X$2:'Portfolio'!$X$89,Portfolio!$O$2:'Portfolio'!$O$89,"=Long",Portfolio!$P$2:'Portfolio'!$P$89,"=Zone3",Portfolio!$Q$2:$Q$89,"=Over 20 years") -> 0
A6: Short_ | B6: =SUMIFS(Portfolio!$X$2:'Portfolio'!$X$89,Portfolio!$O$2:'Portfolio'!$O$89,"=Short",Portfolio!$P$2:'Portfolio'!$P$89,"=Zone1",Portfolio!$Q$2:$Q$89,"=1 month or less") -> 0 | C6: =SUMIFS(Portfolio!$X$2:'Portfolio'!$X$89,Portfolio!$O$2:'Portfolio'!$O$89,"=Short",Portfolio!$P$2:'Portfolio'!$P$89,"=Zone1",Portfolio!$Q$2:$Q$89,"=1 to 3 months") -> 0 | D6: =SUMIFS(Portfolio!$X$2:'Portfolio'!$X$89,Portfolio!$O$2:'Portfolio'!$O$89,"=Short",Portfolio!$P$2:'Portfolio'!$P$89,"=Zone1",Portfolio!$Q$2:$Q$89,"=3 to 6 months") -> 0 | E6: =SUMIFS(Portfolio!$X$2:'Portfolio'!$X$89,Portfolio!$O$2:'Portfolio'!$O$89,"=Short",Portfolio!$P$2:'Portfolio'!$P$89,"=Zone1",Portfolio!$Q$2:$Q$89,"=6 to 12 months") -> 0 | F6: =SUMIFS(Portfolio!$X$2:'Portfolio'!$X$89,Portfolio!$O$2:'Portfolio'!$O$89,"=Short",Portfolio!$P$2:'Portfolio'!$P$89,"=Zone2",Portfolio!$Q$2:$Q$89,"=1 to 1.9 years") -> 0 | G6: =SUMIFS(Portfolio!$X$2:'Portfolio'!$X$89,Portfolio!$O$2:'Portfolio'!$O$89,"=Short",Portfolio!$P$2:'Portfolio'!$P$89,"=Zone2",Portfolio!$Q$2:$Q$89,"=1.9 to 2.8 years") -> 0 | H6: =SUMIFS(Portfolio!$X$2:'Portfolio'!$X$89,Portfolio!$O$2:'Portfolio'!$O$89,"=Short",Portfolio!$P$2:'Portfolio'!$P$89,"=Zone2",Portfolio!$Q$2:$Q$89,"=2.8 to 3.6 years") -> 0 | I6: =SUMIFS(Portfolio!$X$2:'Portfolio'!$X$89,Portfolio!$O$2:'Portfolio'!$O$89,"=Short",Portfolio!$P$2:'Portfolio'!$P$89,"=Zone3",Portfolio!$Q$2:$Q$89,"=3.6 to 4.3 years") -> 0 | J6: =SUMIFS(Portfolio!$X$2:'Portfolio'!$X$89,Portfolio!$O$2:'Portfolio'!$O$89,"=Short",Portfolio!$P$2:'Portfolio'!$P$89,"=Zone3",Portfolio!$Q$2:$Q$89,"=4.3 to 5.7 years") -> 0 | K6: =SUMIFS(Portfolio!$X$2:'Portfolio'!$X$89,Portfolio!$O$2:'Portfolio'!$O$89,"=Short",Portfolio!$P$2:'Portfolio'!$P$89,"=Zone3",Portfolio!$Q$2:$Q$89,"=5.7 to 7.3 years") -> 0 | L6: =SUMIFS(Portfolio!$X$2:'Portfolio'!$X$89,Portfolio!$O$2:'Portfolio'!$O$89,"=Short",Portfolio!$P$2:'Portfolio'!$P$89,"=Zone3",Portfolio!$Q$2:$Q$89,"=7.3 to 9.3 years") -> 0 | M6: =SUMIFS(Portfolio!$X$2:'Portfolio'!$X$89,Portfolio!$O$2:'Portfolio'!$O$89,"=Short",Portfolio!$P$2:'Portfolio'!$P$89,"=Zone3",Portfolio!$Q$2:$Q$89,"=9.3 to 10.6 years") -> 0 | N6: =SUMIFS(Portfolio!$X$2:'Portfolio'!$X$89,Portfolio!$O$2:'Portfolio'!$O$89,"=Short",Portfolio!$P$2:'Portfolio'!$P$89,"=Zone3",Portfolio!$Q$2:$Q$89,"=10.6 to 12 years") -> 0 | O6: =SUMIFS(Portfolio!$X$2:'Portfolio'!$X$89,Portfolio!$O$2:'Portfolio'!$O$89,"=Short",Portfolio!$P$2:'Portfolio'!$P$89,"=Zone3",Portfolio!$Q$2:$Q$89,"=12 to 20 years") -> 0 | P6: =SUMIFS(Portfolio!$X$2:'Portfolio'!$X$89,Portfolio!$O$2:'Portfolio'!$O$89,"=Short",Portfolio!$P$2:'Portfolio'!$P$89,"=Zone3",Portfolio!$Q$2:$Q$89,"=Over 20 years") -> 0
A7: Net_Positions | B7: =B5+B6 -> 1084427.7 | C7: =C5+C6 -> 629383.7 | D7: =D5+D6 -> 0 | E7: =E5+E6 -> 0 | F7: =F5+F6 -> 0 | G7: =G5+G6 -> 0 | H7: =H5+H6 -> 0 | I7: =I5+I6 -> 0 | ... P7: =P5+P6 -> 0
A8: Vertical Disallowance | B8: =MIN(ABS(B5),ABS(B6))*0.05 -> 0 | C8: =MIN(ABS(C5),ABS(C6))*0.05 -> 0 | D8: =MIN(ABS(D5),ABS(D6))*0.05 -> 0 | E8: =MIN(ABS(E5),ABS(E6))*0.05 -> 0 | F8: =MIN(ABS(F5),ABS(F6))*0.05 -> 0 | G8: =MIN(ABS(G5),ABS(G6))*0.05 -> 0 | H8: =MIN(ABS(H5),ABS(H6))*0.05 -> 0 | I8: =MIN(ABS(I5),ABS(I6))*0.05 -> 0 | ... P8: =MIN(ABS(P5),ABS(P6))*0.05 -> 0
A10: Capital Charge for Horizontal Disallowance Zone1 | B10: =MIN(ABS(SUMIF(B7:E7,">0")),ABS(SUMIF(B7:E7,"<0")))*0.4 -> 0
A11: Capital Charge for Horizontal Disallowance Zone2 | B11: =MIN(ABS(SUMIF(F7:H7,">0")),ABS(SUMIF(F7:H7,"<0")))*0.3 -> 0
A12: Capital Charge for Horizontal Disallowance Zone3 | B12: =MIN(ABS(SUMIF(I7:P7,">0")),ABS(SUMIF(I7:P7,"<0")))*0.3 -> 0
A13: Capital Charge for Horizontal Disallowance Zone1&2 | B13: =IF(SUM(B7:E7)*SUM(F7:H7)<0,MIN(ABS(SUM(B7:E7)), ABS(SUM(F7:H7))),0)*0.4 -> 0
A14: Capital Charge for Horizontal Disallowance Zone2&3 | B14: =IF(B13>0,IF(AND(ABS(SUM(F7:H7))>ABS(SUM(B7:E7)),SUM(SUM(F7:H7),SUM(B7:E7))*SUM(I7:P7)<0),MIN(ABS(SUM(SUM(F7:H7),SUM(B7:E7))),ABS(SUM(I7:P7))),0),IF(SUM(I7:P7)*SUM(F7:H7)<0,MIN(ABS(SUM(I7:P7)),ABS(SUM(F7:H7))),0))*0.4 -> 0
A15: Capital Charge for Horizontal Disallowance Zone1&3 | B15: =IF(B14>0,IF(AND(ABS(SUM(I7:P7))>ABS(SUM(F7:H7)),SUM(SUM(I7:P7),SUM(F7:H7))*SUM(B7:E7)<0),MIN(ABS(SUM(SUM(F7:H7),SUM(I7:P7))),ABS(SUM(B7:E7))),0),IF(SUM(SUM(B7:E7),SUM(F7:H7))*SUM(I7:P7)<0,MIN(ABS(SUM(SUM(F7:H7),SUM(B7:E7))),ABS(SUM(I7:P7))),0))*1 -> 0
A16: Capital Charge for Horizontal Disallowance | B16: =SUM(B10:B15) -> 0
A17: Capital Charge for Vertical Disallowance | B17: =SUM(B8:P8) -> 0
A18: Absolute Net Position | B18: =ABS(SUM(B7:P7)) -> 1713811.4
A20: Total Capital Charge for General Market Risk | B20: =SUM(B16:B18) -> 1713811.4 | C20: =B20/10^6 -> 1.7138114
A21: Total Capital Charge for Specific Market Risk | B21: =Portfolio!Y2 -> 8918582.8 | C21: =B21/10^6 -> 8.9185828
A22: Total Capital Charge | B22: =B20+B21 -> 10632394 | C22: =B22/10^6 -> 10.632394 | D22: Mio
